Workbook
Name EPLookupCol: '[1]From Reinsurance Report'!$E$2:$E$4
Name PaidExpLookupCol: '[1]From Monthly Reporting'!$C$4:$C$7
Name PaidIndemLookupCol: '[1]From Monthly Reporting'!$E$4:$E$7
Name PaidStateCol: '[1]From Monthly Reporting'!$A$4:$A$7
Name PremStateCol: '[1]From Reinsurance Report'!$A$2:$A$4
Name RsvLookupCol_Exp: '[1]From Monthly Reporting'!$E$12:$E$15
Name RsvLookupCol_Loss: '[1]From Monthly Reporting'!$D$12:$D$15
Name RsvStateCol: '[1]From Monthly Reporting'!$A$12:$A$15
Name TreatyName: '[1]SetUp & Macro'!$F$8
Name UPRLookupCol: '[1]From Reinsurance Report'!$F$2:$F$4
Name WPLookupCol: '[1]From Reinsurance Report'!$B$2:$B$4

Sheet Instructions
A2: Monthly Reporting Package - Blue Tabs
A4: These should be filled out on a monthly basis
A6: Please only input data in the yellow shaded "input" areas. All other fields contain formulas that will automatically fill in once "input" areas are completed.
A8: The "MTHLY-State" sheets will feed into the "MTHLY-TOTAL" sheet. The only fields on the "MTHLY-TOTAL" sheet that should be filled are the "Polices in Force" field.
A10: The "Cash Settlement" sheet calculates from the "MTHLY-TOTAL" sheet. The "Ending Balance Due SNIC" shows the amount due to USIC for the reported month.
A13: Year- End Reporting Package - Yellow Tabs
A15: These should only be filled out when requested at year end
A17: Please input your data in the PINK highlighted cells only.
A19: Please provide a separate workbook for each company (SNIC, NSIC or USIC) if applicable and each treaty (contract) period.
A21: All data provided for the accounting months must reconcile to previous monthly exhibits. If you find any errors/differences, you must provide revised exhibits for the applicable reporting period(s).

Sheet Expenses Def.
A2: EXTRACTED FROM NAIC INSTRUCTION
B4: Expenses Definition
A8: The loss adjustment expenses used to be divided into "allocated" and "unallocated," which were terms that were
A9: never clearly defined. Effective January 1, 1998, a detailed definition of these expenses was adopted. The distinction
A10: is now between "defense & Cost Containment" and "Adjusting & Other." The loss adjustment expenses are separated
A11: with the intent of identifying the "Defense & Cost Containment" expenses as those, which are correlated with the loss
A12: amounts, and the "Adjusting & Other" as those expenses, which are correlated with claim, count or are general loss
A13: adjusting expenses. It is the character of the expenses that is most important, not whether the expenses were internal
A14: or external to the insurer.
A17: Defense & Cost Containment expenses include defense, litigation and cost containment expenses, whether internal or
A18: external. "Defense" means defense by the insurer in a contentious situation, whether a first party or a third party claim. The
A19: fees charged for insurer employees should include overhead, just as an outside firm's charges would include. The expenses
A20: exclude expenses incurred in the determination of coverage. These expenses include the following items:
A22: 1 | B22: Surveillance expenses;
A23: 2 | B23: Fixed amounts for cost containment expenses;
A24: 3 | B24: Litigation management expenses;
A25: 4 | B25: Loss adjustment expenses for participation in voluntary and involuntary market pools if reported by accident year;
A26: 5 | B26: Fees or salaries for appraisers, private investigators, hearing representatives, reinspectors and fraud investigators,
B27: if working in defense of a claim, and fees or salaries for rehabilitation nurses, if such cost is not included in losses;
A28: 6 | B28: Attorney fees incurred owing to a duty to defend, even when other coverage does not exist; and
A29: 7 | B29: The cost of engaging experts.
A31: Adjusting & Other expenses are those expenses other than those above and which have been assigned to the "Loss Adjustment
A32: Expense" group in the Underwriting and Investment Exhibit – Part 4 – Expenses. These expenses include the following items:
A34: 1 | B34: Fees of adjusters and settling agents (but not if engaged in a contentious defense);
A35: 2 | B35: Loss adjustment expenses for participation in voluntary and involuntary market pools if reported by calendar year;
A36: 3 | B36: Attorney fees incurred in the determination of coverage, including litigation between the insurer and the policyholder;
A37: 4 | B37: Fees or salaries for appraisers, private investigators, hearing representatives, reinspectors and fraud investigators,
B38: if working in the capacity of an adjuster.
A41: The foregoing list is not intended to be all-inclusive. We are relying on the insurers to use reasonable judgment in particular
A42: situations.
A44: The "Defense & Cost Containment" expenses should be assigned to the accident year in which the associated losses were
A45: assigned. The "Adjusting & Other" expenses can be assigned in any justifiable way among the accident years. The preferred
A46: way is to apportion these expenses in proportion to the number of claims reported, closed, or outstanding each year.

Sheet Cash Settlement
A1: PRODUCER: FUTURISTIC UNDERWRITERS LLC. | D1: Input area | F1: Input area | O1: Q/S | P1: 1
A2: COMPANY: SOUTHLAKE SPECIALTY INSURANCE COMPANY | O2: CF | P2: 0.05
O3: Comm | P3: 0.29
O4: Comm | P4: 0.29
A5: TREATY YEAR : 5/1/2020 | O5: BB | P5: 0.004
O6: ULAE | P6: 0.07
O7: XOL | P7: 0
B8: 100% QUOTA SHARE | O8: LR Cap | P8: 0.02
B9: FOR THE MONTH OF | C9: 46142
D11: (2)
D12: REINSURERS | L12: (3)
C13: (1) | D13: AMOUNT | L13: STATE NAT'L
C14: TOTAL | D14: SSIC | E14: ISMIE | F14: Ambridge Re | G14: Liberty Mutual Re | L14: AMOUNT
C15: 100 % | D15: 1 | E15: 0 | F15: 0 | G15: 0 | L15: =+C15-D15-E15-F15-G15-H15-I15-J15-K15 -> 0
A16: 1. | B16: QUOTA SHARE PREMIUMS WRITTEN | D16: =+C16*D15 -> 0 | E16: =+C16*E15 -> 0 | F16: =+C16*F15 -> 0 | G16: =+C16*G15 -> 0 | H16: =+C16*H15 -> 0 | I16: =+C16*I15 -> 0 | J16: =+C16*J15 -> 0 | K16: =+C16*K15 -> 0 | L16: =+C16-D16-E16-F16-G16-H16-I16-J16-K16 -> 0
A17: 2. | B17: POLICY FEES: | C17: ='MTHLY-TOTAL'!E13 -> 0 | D17: =+C17*$D$15 -> 0 | E17: =+C17*$E$15 -> 0 | F17: =+C17*$F$15 -> 0 | G17: =+C17*$G$15 -> 0 | H17: =+C17*$H$15 -> 0 | I17: =+C17*$I$15 -> 0 | J17: =+C17*$J$15 -> 0 | K17: =+C17*$K$15 -> 0 | L17: =+C17-D17-E17-F17-G17-H17-I17-J17-K17 -> 0
A18: 3. | B18: NET PREMIUMS INCLUDING POLICY FEES | C18: =+C16+C17 -> 0 | D18: =+D16+D17 -> 0 | E18: =+E16+E17 -> 0 | F18: =+F16+F17 -> 0 | G18: =+G16+G17 -> 0 | H18: =+H16+H17 -> 0 | I18: =+I16+I17 -> 0 | J18: =+J16+J17 -> 0 | ... L18: =+L16+L17 -> 0
A20: 4. | B20: COLLECTED PREMIUMS | C20: ='MTHLY-TOTAL'!E14 -> -12464.16 | D20: =+C20*D$15 -> -12464.16 | E20: =+C20*E$15 -> 0 | F20: =+C20*F$15 -> 0 | G20: =+C20*G$15 -> 0 | H20: =+C20*H$15 -> 0 | I20: =+C20*I$15 -> 0 | J20: =+C20*J$15 -> 0 | K20: =+C20*K$15 -> 0 | L20: =+C20-D20-E20-F20-G20-H20-I20-J20-K20 -> 0
A21: 5. | B21: POLICY FEES: | C21: ='MTHLY-TOTAL'!E15 -> 0 | D21: =+C21*D$15 -> 0 | E21: =+C21*E$15 -> 0 | F21: =+C21*F$15 -> 0 | G21: =+C21*G$15 -> 0 | H21: =+C21*H$15 -> 0 | I21: =+C21*I$15 -> 0 | J21: =+C21*J$15 -> 0 | K21: =+C21*K$15 -> 0 | L21: =+C21-D21-E21-F21-G21-H21-I21-J21-K21 -> 0
A22: 6. | B22: NET COLLECTED PREMIUMS INCLUDING POLICY FEES | C22: =C20+C21 -> -12464.16 | D22: =D20+D21 -> -12464.16 | E22: =E20+E21 -> 0 | F22: =F20+F21 -> 0 | G22: =G20+G21 -> 0 | H22: =H20+H21 -> 0 | I22: =I20+I21 -> 0 | J22: =J20+J21 -> 0 | ... L22: =L20+L21 -> 0
A24: 7. | B24: LESS: COMMISSION DUE | C24: =D24+E24+F24+G24+H24+I24+J24+K24 -> -3614.6064 | D24: =D20*P3 -> -3614.6064 | E24: =E20*P3 -> 0 | F24: =F20*P3 -> 0 | G24: =G20*P3 -> 0 | H24: =H20*P3 -> 0 | I24: =I20*P3 -> 0 | J24: =J20*P3 -> 0 | K24: =K20*P3 -> 0 | L24: =C24-D24-E24-F24-G24-H24-I24-J24-K24 -> 0
B25: LESS: POLICY FEES | C25: =+C21 -> 0 | D25: =+D21 -> 0 | E25: =+E21 -> 0 | F25: =+F21 -> 0 | G25: =+G21 -> 0 | H25: =+H21 -> 0 | I25: =+I21 -> 0 | J25: =+J21 -> 0 | ... L25: =+L21 -> 0
B26: TOTAL COMMISSION DUE | C26: =SUM(C23:C25) -> -3614.6064 | D26: =SUM(D23:D25) -> -3614.6064 | E26: =SUM(E23:E25) -> 0 | F26: =SUM(F23:F25) -> 0 | G26: =SUM(G23:G25) -> 0 | H26: =SUM(H23:H25) -> 0 | I26: =SUM(I23:I25) -> 0 | J26: =SUM(J23:J25) -> 0 | ... L26: =SUM(L23:L25) -> 0
A28: 8. | B28: LESS: LOSS FUNDING | C28: 0 | D28: =+C28*$D$15 -> 0 | E28: =+C28*$E$15 -> 0 | F28: =+C28*$F$15 -> 0 | G28: =+C28*$G$15 -> 0 | H28: =+C28*$H$15 -> 0 | I28: =+C28*$I$15 -> 0 | J28: =+C28*$J$15 -> 0 | K28: =+C28*$K$15 -> 0 | L28: =+C28-D28-E28-F28-G28-H28-I28-J28-K28 -> 0
B29: LESS: LOSSES PAID (net of salvage & subro) | C29: ='MTHLY-TOTAL'!E19 -> 207475.83 | D29: =+C29*$D$15 -> 207475.83 | E29: =+C29*$E$15 -> 0 | F29: =+C29*$F$15 -> 0 | G29: =+C29*$G$15 -> 0 | H29: =+C29*$H$15 -> 0 | I29: =+C29*$I$15 -> 0 | J29: =+C29*$J$15 -> 0 | K29: =+C29*$K$15 -> 0 | L29: =+C29-D29-E29-F29-G29-H29-I29-J29-K29 -> 0
B30: LESS: UNALLOCATED LOSS ADJUSTMENT EXPENSE | C30: ='MTHLY-TOTAL'!C29 -> 0 | D30: =+C30*$D$15 -> 0 | E30: =+C30*$E$15 -> 0 | F30: =+C30*$F$15 -> 0 | G30: =+C30*$G$15 -> 0 | H30: =+C30*$H$15 -> 0 | I30: =+C30*$I$15 -> 0 | J30: =+C30*$J$15 -> 0 | K30: =+C30*$K$15 -> 0 | L30: =+C30-D30-E30-F30-G30-H30-I30-J30-K30 -> 0
B31: LESS: DEFENSE AND COST CONTAINMENT EXPENSE PAID (DCC) | C31: ='MTHLY-TOTAL'!E20 -> 0 | D31: =+C31*$D$15 -> 0 | E31: =+C31*$E$15 -> 0 | F31: =+C31*$F$15 -> 0 | G31: =+C31*$G$15 -> 0 | H31: =+C31*$H$15 -> 0 | I31: =+C31*$I$15 -> 0 | J31: =+C31*$J$15 -> 0 | K31: =+C31*$K$15 -> 0 | L31: =+C31-D31-E31-F31-G31-H31-I31-J31-K31 -> 0
B32: LESS: ADJUSTING & OTHER EXPENSE PAID (A&O) | C32: ='MTHLY-TOTAL'!E21 -> -872.4912 | D32: =+$C32*D15 -> -872.4912 | E32: =+$C32*E15 -> 0 | F32: =+$C32*F15 -> 0 | G32: =+$C32*G15 -> 0 | H32: =+C32*$H$15 -> 0 | I32: =+C32*$I$15 -> 0 | J32: =+C32*$J$15 -> 0 | K32: =+C32*$K$15 -> 0 | L32: =+C32-D32-E32-F32-G32-H32-I32-J32-K32 -> 0
B33: TOTAL LOSSES PAID | C33: =SUM(C28:C32) -> 206603.34 | D33: =SUM(D28:D32) -> 206603.34 | E33: =SUM(E28:E32) -> 0 | F33: =SUM(F28:F32) -> 0 | G33: =SUM(G28:G32) -> 0 | H33: =SUM(H28:H32) -> 0 | I33: =SUM(I28:I32) -> 0 | J33: =SUM(J28:J32) -> 0 | ... L33: =SUM(L28:L32) -> 0
B35: SUBTOTAL DUE | C35: =C22-C26-C33 -> -215452.89 | D35: =D22-D26-D33 -> -215452.89 | E35: =E22-E26-E33 -> 0 | F35: =F22-F26-F33 -> 0 | G35: =G22-G26-G33 -> 0 | H35: =H22-H26-H33 -> 0 | I35: =I22-I26-I33 -> 0 | J35: =J22-J26-J33 -> 0 | ... L35: =L22-L26-L33 -> 0
A37: 9. | B37: CEDING FEE DUE | L37: =C22*$P$2 -> -623.208 | M37: **
A38: 10. | B38: BOARDS & BUREAUS DUE | D38: =-L38 -> 0 | L38: =+C18*$P$5 -> 0
A39: 11. | B39: XOL FEES DUE | L39: =+C18*$P$7 -> 0
A40: 12. | B40: LR Cap | D40: =-L40 -> 0 | L40: =+C18*(P8) -> 0
B41: TOTAL TAXES & FEES DUE | L41: =SUM(L37:L40) -> -623.208
B44: TOTAL BALANCE DUE REINSURERS | C44: ……………………. | D44: =D35+D38+D39+D40 -> -215452.89 | E44: =+E35+E41 -> 0 | F44: =+F35+F41 -> 0 | G44: =+G35+G41 -> 0 | H44: =+H35+H41 -> 0 | I44: =+I35+I41 -> 0 | J44: =+J35+J41 -> 0 | K44: =+K35+K41 -> 0
B45: TOTAL BALANCE DUE SSIC | C45: …………………………………………… | L45: =+L35+L41 -> -623.208
B47: Beginning Balance Due TO/(FROM) SSIC: | C47: carry from last month | L47: 0
B49: Less: Amounts Paid TO/(FROM) SSIC | L49: 0
B51: Ending Balance Due TO/(FROM) SSIC: | L51: =+L45+L49 -> -623.208
...

Sheet MTHLY-TOTAL
A1: =+'Cash Settlement'!A2 -> COMPANY: SOUTHLAKE SPECIALTY INSURANCE COMPANY
A2: =+'Cash Settlement'!A1 -> PRODUCER: FUTURISTIC UNDERWRITERS LLC. | D2: Input area
A3: EXHIBIT OF PREMIUMS AND LOSSES
A4: =+'Cash Settlement'!B9 -> FOR THE MONTH OF | C4: ='Cash Settlement'!C9 -> 46142
A6: TOTAL PROGRAM BY LINE OF BUSINESS
A8: STATE All States
B9: 9 | C9: 19.4 | D9: 21.2
A10: ='Cash Settlement'!A5 -> TREATY YEAR : 5/1/2020 | B10: Comm'l Auto | C10: Other Comm'l | D10: Comm'l Auto | E10: TOTALS
B11: Inland Marine | C11: Auto Liab | D11: Phys. Damage
A12: Premiums Written | B12: =SUM('MTHLY-AL:MTHLY-WY'!B14) -> 0 | C12: =SUM('MTHLY-AL:MTHLY-WY'!C14) -> 0 | D12: =SUM('MTHLY-AL:MTHLY-WY'!D14) -> -12464.16 | E12: =SUM(B12:D12) -> -12464.16
A13: Policy Fees Written | B13: =SUM('MTHLY-AL:MTHLY-WY'!B15) -> 0 | C13: =SUM('MTHLY-AL:MTHLY-WY'!C15) -> 0 | D13: =SUM('MTHLY-AL:MTHLY-WY'!D15) -> 0 | E13: =SUM(B13:D13) -> 0
A14: Premiums Collected | B14: =SUM('MTHLY-AL:MTHLY-WY'!B16) -> 0 | C14: =SUM('MTHLY-AL:MTHLY-WY'!C16) -> 0 | D14: =SUM('MTHLY-AL:MTHLY-WY'!D16) -> -12464.16 | E14: =SUM(B14:D14) -> -12464.16
A15: Policy Fees Collected | B15: =SUM('MTHLY-AL:MTHLY-WY'!B17) -> 0 | C15: =SUM('MTHLY-AL:MTHLY-WY'!C17) -> 0 | D15: =SUM('MTHLY-AL:MTHLY-WY'!D17) -> 0 | E15: =SUM(B15:D15) -> 0
A16: Front/Ceding Fees | B16: =ROUND(SUM(B12:B13)*'Cash Settlement'!$P$2,2) -> 0 | C16: =ROUND(SUM(C12:C13)*'Cash Settlement'!$P$2,2) -> 0 | D16: =ROUND(SUM(D12:D13)*'Cash Settlement'!$P$2,2) -> -623.21 | E16: =SUM(B16:D16) -> -623.21
A17: Premium Taxes | B17: =SUM('MTHLY-AL:MTHLY-WY'!B18) -> 0 | C17: =SUM('MTHLY-AL:MTHLY-WY'!C18) -> 0 | D17: =SUM('MTHLY-AL:MTHLY-WY'!D18) -> 0 | E17: =SUM(B17:D17) -> 0
A18: Boards & Bureau | B18: =ROUND((B12+B13)*'Cash Settlement'!$P$5,2) -> 0 | C18: =ROUND((C12+C13)*'Cash Settlement'!$P$5,2) -> 0 | D18: =ROUND((D12+D13)*'Cash Settlement'!$P$5,2) -> -49.86 | E18: =SUM(B18:D18) -> -49.86
A19: Losses Paid (Net of Salvage & Subrogation) | B19: =SUM('MTHLY-AL:MTHLY-WY'!B19) -> 0 | C19: =SUM('MTHLY-AL:MTHLY-WY'!C19) -> 0 | D19: =SUM('MTHLY-AL:MTHLY-WY'!D19) -> 207475.83 | E19: =SUM(B19:D19) -> 207475.83
A20: Defense & Cost Containment Expenses Paid - (ALAE) | B20: =SUM('MTHLY-AL:MTHLY-WY'!B20) -> 0 | C20: =SUM('MTHLY-AL:MTHLY-WY'!C20) -> 0 | D20: =SUM('MTHLY-AL:MTHLY-WY'!D20) -> 0 | E20: =SUM(B20:D20) -> 0
A21: Adjusting & Other Expenses Paid - (ULAE-TPA Fees) | B21: =SUM('MTHLY-AL:MTHLY-WY'!B21) -> 0 | C21: =SUM('MTHLY-AL:MTHLY-WY'!C21) -> 0 | D21: =SUM('MTHLY-AL:MTHLY-WY'!D21) -> -872.4912 | E21: =SUM(B21:D21) -> -872.4912
A22: Premium Earned - YTD | B22: =SUM('MTHLY-AL:MTHLY-WY'!B22) -> 0 | C22: =SUM('MTHLY-AL:MTHLY-WY'!C22) -> 0 | D22: =SUM('MTHLY-AL:MTHLY-WY'!D22) -> 1170452 | E22: =SUM(B22:D22) -> 1170452
A23: Policy Fees Earned - YTD | B23: =SUM('MTHLY-AL:MTHLY-WY'!B23) -> 0 | C23: =SUM('MTHLY-AL:MTHLY-WY'!C23) -> 0 | D23: =SUM('MTHLY-AL:MTHLY-WY'!D23) -> 0 | E23: =SUM(B23:D23) -> 0
A24: Unearned Premium Reserves | B24: =SUM('MTHLY-AL:MTHLY-WY'!B24) -> 0 | C24: =SUM('MTHLY-AL:MTHLY-WY'!C24) -> 0 | D24: =SUM('MTHLY-AL:MTHLY-WY'!D24) -> 889754.56 | E24: =SUM(B24:D24) -> 889754.56
A25: NUMBER OF POLICIES IN FORCE | B25: 0 | C25: 0 | D25: ='Policies In force'!E61 -> 283 | E25: =D25 -> 283
A26: Direct Losses Unpaid | B26: =SUM('MTHLY-AL:MTHLY-WY'!B25) -> 0 | C26: =SUM('MTHLY-AL:MTHLY-WY'!C25) -> 0 | D26: =SUM('MTHLY-AL:MTHLY-WY'!D25) -> 54333 | E26: =SUM(B26:D26) -> 54333
A27: Defense & Cost Containment Unpaid - (ALAE) | B27: =SUM('MTHLY-AL:MTHLY-WY'!B26) -> 0 | C27: =SUM('MTHLY-AL:MTHLY-WY'!C26) -> 0 | D27: =SUM('MTHLY-AL:MTHLY-WY'!D26) -> 14195 | E27: =SUM(B27:D27) -> 14195
A28: Adjusting & Other Unpaid - (ULAE-TPA Fees) | B28: =SUM('MTHLY-AL:MTHLY-WY'!B27) -> 0 | C28: =SUM('MTHLY-AL:MTHLY-WY'!C27) -> 0 | D28: =SUM('MTHLY-AL:MTHLY-WY'!D27) -> 0 | E28: =SUM(B28:D28) -> 0
B29: =SUM('MTHLY-AL:MTHLY-WY'!B28) -> 0 | C29: =SUM('MTHLY-AL:MTHLY-WY'!C28) -> 0 | D29: =SUM('MTHLY-AL:MTHLY-WY'!D28) -> 0 | E29: =SUM(B29:D29) -> 0
A31: Submitted by: ______________

Sheet MTHLY-AL
A1: =+'Cash Settlement'!A2 -> COMPANY: SOUTHLAKE SPECIALTY INSURANCE COMPANY
A2: =+'Cash Settlement'!A1 -> PRODUCER: FUTURISTIC UNDERWRITERS LLC. | D2: Input area
A3: EXHIBIT OF PREMIUMS AND LOSSES
A4: FOR THE MONTH OF | C4: =+'Cash Settlement'!C9 -> 46142
A6: BY LINE, BY STATE
B11: 19.3 | C11: 19.4 | D11: 21.2
A12: =+'MTHLY-TOTAL'!A10 -> TREATY YEAR : 5/1/2020 | B12: Comm'l Auto | C12: Other Comm'l | D12: Comm'l Auto | E12: TOTALS
B13: No-Fault | C13: Auto Liab | D13: Phys. Damage
A14: Premiums Written | B14: 0 | C14: 0 | D14: 0 | E14: =SUM(B14:D14) -> 0
A15: Policy Fees Written | B15: 0 | C15: 0 | D15: 0 | E15: =SUM(B15:D15) -> 0
A16: Premiums Collected | B16: 0 | C16: 0 | D16: 0 | E16: =SUM(B16:D16) -> 0
A17: Policy Fees Collected | B17: 0 | C17: 0 | D17: 0 | E17: =SUM(B17:D17) -> 0
A18: Premium Taxes | B18: =(B14+B15)*'Tax Rates'!$B$7 -> 0 | C18: =(C14+C15)*'Tax Rates'!$B$7 -> 0 | D18: =(D14+D15)*'Tax Rates'!$B$7 -> 0 | E18: =SUM(B18:D18) -> 0
A19: Losses Paid (Net of Salvage & Subrogation) | B19: 0 | C19: 0 | D19: 0 | E19: =SUM(B19:D19) -> 0
A20: Defense & Cost Containment Expenses Paid | B20: 0 | C20: 0 | D20: 0 | E20: =SUM(B20:D20) -> 0
A21: Adjusting & Other Expenses Paid | B21: 0 | C21: 0 | D21: 0 | E21: =SUM(B21:D21) -> 0
A22: Premium Earned - YTD | B22: 0 | C22: 0 | D22: 0 | E22: =SUM(B22:D22) -> 0
A23: Policy Fees Earned - YTD | B23: 0 | C23: 0 | D23: 0 | E23: =SUM(B23:D23) -> 0
A24: Unearned Premium Reserves | B24: 0 | C24: 0 | D24: 0 | E24: =SUM(B24:D24) -> 0
A25: Direct Losses Unpaid | B25: 0 | C25: 0 | D25: 0 | E25: =SUM(B25:D25) -> 0
A26: Defense & Cost Containment Unpaid | B26: 0 | C26: 0 | D26: 0 | E26: =SUM(B26:D26) -> 0
A27: Adjusting & Other Unpaid | B27: 0 | C27: 0 | D27: 0 | E27: =SUM(B27:D27) -> 0
A29: ='MTHLY-TOTAL'!A31 -> Submitted by: ______________

Sheet MTHLY-AK
A1: =+'Cash Settlement'!A2 -> COMPANY: SOUTHLAKE SPECIALTY INSURANCE COMPANY
A2: =+'Cash Settlement'!A1 -> PRODUCER: FUTURISTIC UNDERWRITERS LLC. | D2: Input area
A3: EXHIBIT OF PREMIUMS AND LOSSES
A4: FOR THE MONTH OF | C4: =+'Cash Settlement'!C9 -> 46142
A6: BY LINE, BY STATE
B11: 19.3 | C11: 19.4 | D11: 21.2
A12: =+'MTHLY-TOTAL'!A10 -> TREATY YEAR : 5/1/2020 | B12: Comm'l Auto | C12: Other Comm'l | D12: Comm'l Auto | E12: TOTALS
B13: No-Fault | C13: Auto Liab | D13: Phys. Damage
A14: Premiums Written | B14: 0 | C14: 0 | D14: 0 | E14: =SUM(B14:D14) -> 0
A15: Policy Fees Written | B15: 0 | C15: 0 | D15: 0 | E15: =SUM(B15:D15) -> 0
A16: Premiums Collected | B16: 0 | C16: 0 | D16: 0 | E16: =SUM(B16:D16) -> 0
A17: Policy Fees Collected | B17: 0 | C17: 0 | D17: 0 | E17: =SUM(B17:D17) -> 0
A18: Premium Taxes | B18: =(B14+B15)*'Tax Rates'!$B$8 -> 0 | C18: =(C14+C15)*'Tax Rates'!$B$8 -> 0 | D18: =(D14+D15)*'Tax Rates'!$B$8 -> 0 | E18: =SUM(B18:D18) -> 0
A19: Losses Paid (Net of Salvage & Subrogation) | B19: 0 | C19: 0 | D19: 0 | E19: =SUM(B19:D19) -> 0
A20: Defense & Cost Containment Expenses Paid | B20: 0 | C20: 0 | D20: 0 | E20: =SUM(B20:D20) -> 0
A21: Adjusting & Other Expenses Paid | B21: 0 | C21: 0 | D21: 0 | E21: =SUM(B21:D21) -> 0
A22: Premium Earned - YTD | B22: 0 | C22: 0 | D22: 0 | E22: =SUM(B22:D22) -> 0
A23: Policy Fees Earned - YTD | B23: 0 | C23: 0 | D23: 0 | E23: =SUM(B23:D23) -> 0
A24: Unearned Premium Reserves | B24: 0 | C24: 0 | D24: 0 | E24: =SUM(B24:D24) -> 0
A25: Direct Losses Unpaid | B25: 0 | C25: 0 | D25: 0 | E25: =SUM(B25:D25) -> 0
A26: Defense & Cost Containment Unpaid | B26: 0 | C26: 0 | D26: 0 | E26: =SUM(B26:D26) -> 0
A27: Adjusting & Other Unpaid | B27: 0 | C27: 0 | D27: 0 | E27: =SUM(B27:D27) -> 0
A29: ='MTHLY-TOTAL'!A31 -> Submitted by: ______________

Sheet MTHLY-AR
A1: =+'Cash Settlement'!A2 -> COMPANY: SOUTHLAKE SPECIALTY INSURANCE COMPANY
A2: =+'Cash Settlement'!A1 -> PRODUCER: FUTURISTIC UNDERWRITERS LLC. | D2: Input area
A3: EXHIBIT OF PREMIUMS AND LOSSES
A4: FOR THE MONTH OF | C4: =+'Cash Settlement'!C9 -> 46142
A6: BY LINE, BY STATE
B11: 19.3 | C11: 19.4 | D11: 21.2
A12: =+'MTHLY-TOTAL'!A10 -> TREATY YEAR : 5/1/2020 | B12: Comm'l Auto | C12: Other Comm'l | D12: Comm'l Auto | E12: TOTALS
B13: No-Fault | C13: Auto Liab | D13: Phys. Damage
A14: Premiums Written | B14: 0 | C14: 0 | D14: 0 | E14: =SUM(B14:D14) -> 0
A15: Policy Fees Written | B15: 0 | C15: 0 | D15: 0 | E15: =SUM(B15:D15) -> 0
A16: Premiums Collected | B16: 0 | C16: 0 | D16: 0 | E16: =SUM(B16:D16) -> 0
A17: Policy Fees Collected | B17: 0 | C17: 0 | D17: 0 | E17: =SUM(B17:D17) -> 0
A18: Premium Taxes | B18: =(B14+B15)*'Tax Rates'!$B$10 -> 0 | C18: =(C14+C15)*'Tax Rates'!$B$10 -> 0 | D18: =(D14+D15)*'Tax Rates'!$B$10 -> 0 | E18: =SUM(B18:D18) -> 0
A19: Losses Paid (Net of Salvage & Subrogation) | B19: 0 | C19: 0 | D19: 0 | E19: =SUM(B19:D19) -> 0
A20: Defense & Cost Containment Expenses Paid | B20: 0 | C20: 0 | D20: 0 | E20: =SUM(B20:D20) -> 0
A21: Adjusting & Other Expenses Paid | B21: 0 | C21: 0 | D21: 0 | E21: =SUM(B21:D21) -> 0
A22: Premium Earned - YTD | B22: 0 | C22: 0 | D22: 0 | E22: =SUM(B22:D22) -> 0
A23: Policy Fees Earned - YTD | B23: 0 | C23: 0 | D23: 0 | E23: =SUM(B23:D23) -> 0
A24: Unearned Premium Reserves | B24: 0 | C24: 0 | D24: 0 | E24: =SUM(B24:D24) -> 0
A25: Direct Losses Unpaid | B25: 0 | C25: 0 | D25: 0 | E25: =SUM(B25:D25) -> 0
A26: Defense & Cost Containment Unpaid | B26: 0 | C26: 0 | D26: 0 | E26: =SUM(B26:D26) -> 0
A27: Adjusting & Other Unpaid | B27: 0 | C27: 0 | D27: 0 | E27: =SUM(B27:D27) -> 0
A29: ='MTHLY-TOTAL'!A31 -> Submitted by: ______________

Sheet MTHLY-AZ
A1: =+'Cash Settlement'!A2 -> COMPANY: SOUTHLAKE SPECIALTY INSURANCE COMPANY
A2: =+'Cash Settlement'!A1 -> PRODUCER: FUTURISTIC UNDERWRITERS LLC. | D2: Input area
A3: EXHIBIT OF PREMIUMS AND LOSSES
A4: FOR THE MONTH OF | C4: =+'Cash Settlement'!C9 -> 46142
A6: BY LINE, BY STATE
B11: 9 | C11: 19.4 | D11: 21.2
A12: =+'MTHLY-TOTAL'!A10 -> TREATY YEAR : 5/1/2020 | B12: Comm'l Auto | C12: Other Comm'l | D12: Comm'l Auto | E12: TOTALS
B13: Inland Marine | C13: Auto Liab | D13: Phys. Damage
A14: Premiums Written | B14: 0 | C14: 0 | D14: 0 | E14: =SUM(B14:D14) -> 0
A15: Policy Fees Written | B15: 0 | C15: 0 | D15: 0 | E15: =SUM(B15:D15) -> 0
A16: Premiums Collected | B16: 0 | C16: 0 | D16: 0 | E16: =SUM(B16:D16) -> 0
A17: Policy Fees Collected | B17: 0 | C17: 0 | D17: 0 | E17: =SUM(B17:D17) -> 0
A18: Premium Taxes | B18: =(B14+B15)*'Tax Rates'!$B$9 -> 0 | C18: =(C14+C15)*'Tax Rates'!$B$9 -> 0 | E18: =SUM(B18:D18) -> 0
A19: Losses Paid (Net of Salvage & Subrogation) | B19: 0 | C19: 0 | D19: 0 | E19: =SUM(B19:D19) -> 0
A20: Defense & Cost Containment Expenses Paid - (ALAE) | B20: 0 | C20: 0 | D20: 0 | E20: =SUM(B20:D20) -> 0
A21: Adjusting & Other Expenses Paid - (ULAE-TPA Fees) | B21: 0 | C21: 0 | D21: 0 | E21: =SUM(B21:D21) -> 0
A22: Premium Earned - YTD | B22: 0 | C22: 0 | D22: 27205.81 | E22: =SUM(B22:D22) -> 27205.81
A23: Policy Fees Earned - YTD | B23: 0 | C23: 0 | D23: 0 | E23: =SUM(B23:D23) -> 0
A24: Unearned Premium Reserves | B24: 0 | C24: 0 | D24: 21692.96 | E24: =SUM(B24:D24) -> 21692.96
A25: Direct Losses Unpaid | B25: 0 | C25: 0 | D25: 0 | E25: =SUM(B25:D25) -> 0
A26: Defense & Cost Containment Unpaid -- (ALAE) | B26: 0 | C26: 0 | D26: 0 | E26: =SUM(B26:D26) -> 0
A27: Adjusting & Other Unpaid - (ULAE-TPA Fees) | B27: 0 | C27: 0 | D27: 0 | E27: =SUM(B27:D27) -> 0
B28: 0 | C28: 0 | D28: 0 | E28: =SUM(B28:D28) -> 0
A30: ='MTHLY-TOTAL'!A31 -> Submitted by: ______________

Sheet MTHLY-CA
A1: =+'Cash Settlement'!A2 -> COMPANY: SOUTHLAKE SPECIALTY INSURANCE COMPANY
A2: =+'Cash Settlement'!A1 -> PRODUCER: FUTURISTIC UNDERWRITERS LLC. | D2: Input area
A3: EXHIBIT OF PREMIUMS AND LOSSES
A4: FOR THE MONTH OF | C4: =+'Cash Settlement'!C9 -> 46142
A6: BY LINE, BY STATE
B11: 9 | C11: 19.4 | D11: 21.2
A12: =+'MTHLY-TOTAL'!A10 -> TREATY YEAR : 5/1/2020 | B12: Comm'l Auto | C12: Other Comm'l | D12: Comm'l Auto | E12: TOTALS
B13: Inland Marine | C13: Auto Liab | D13: Phys. Damage
A14: Premiums Written | B14: 0 | C14: 0 | D14: -10318.74 | E14: =SUM(B14:D14) -> -10318.74
A15: Policy Fees Written | B15: 0 | C15: 0 | D15: 0 | E15: =SUM(B15:D15) -> 0
A16: Premiums Collected | B16: 0 | C16: 0 | D16: -10318.74 | E16: =SUM(B16:D16) -> -10318.74
A17: Policy Fees Collected | B17: 0 | C17: 0 | D17: 0 | E17: =SUM(B17:D17) -> 0
A18: Premium Taxes | B18: =(B14+B15)*'Tax Rates'!$B$11 -> 0 | C18: =(C14+C15)*'Tax Rates'!$B$11 -> 0 | E18: =SUM(B18:D18) -> 0
A19: Losses Paid (Net of Salvage & Subrogation) | B19: 0 | C19: 0 | D19: 80975.83 | E19: =SUM(B19:D19) -> 80975.83
A20: Defense & Cost Containment Expenses Paid - (ALAE) | B20: 0 | C20: 0 | D20: 0 | E20: =SUM(B20:D20) -> 0
A21: Adjusting & Other Expenses Paid - (ULAE-TPA Fees) | B21: 0 | C21: 0 | D21: -722.3118 | E21: =SUM(B21:D21) -> -722.3118
A22: Premium Earned - YTD | B22: 0 | C22: 0 | D22: 708172.81 | E22: =SUM(B22:D22) -> 708172.81
A23: Policy Fees Earned - YTD | B23: 0 | C23: 0 | D23: 0 | E23: =SUM(B23:D23) -> 0
A24: Unearned Premium Reserves | B24: 0 | C24: 0 | D24: 510480.07 | E24: =SUM(B24:D24) -> 510480.07
A25: Direct Losses Unpaid | B25: 0 | C25: 0 | D25: 17500 | E25: =SUM(B25:D25) -> 17500
A26: Defense & Cost Containment Unpaid - (ALAE) | B26: 0 | C26: 0 | D26: 5000 | E26: =SUM(B26:D26) -> 5000
A27: Adjusting & Other Unpaid - (ULAE-TPA Fees) | B27: 0 | C27: 0 | D27: 0 | E27: =SUM(B27:D27) -> 0
B28: 0 | C28: 0 | D28: 0 | E28: =SUM(B28:D28) -> 0
A30: ='MTHLY-TOTAL'!A31 -> Submitted by: ______________

Sheet MTHLY-CO
A1: =+'Cash Settlement'!A2 -> COMPANY: SOUTHLAKE SPECIALTY INSURANCE COMPANY
A2: =+'Cash Settlement'!A1 -> PRODUCER: FUTURISTIC UNDERWRITERS LLC. | D2: Input area
A3: EXHIBIT OF PREMIUMS AND LOSSES
A4: FOR THE MONTH OF | C4: =+'Cash Settlement'!C9 -> 46142
A6: BY LINE, BY STATE
B11: 19.3 | C11: 19.4 | D11: 21.2
A12: =+'MTHLY-TOTAL'!A10 -> TREATY YEAR : 5/1/2020 | B12: Comm'l Auto | C12: Other Comm'l | D12: Comm'l Auto | E12: TOTALS
B13: No-Fault | C13: Auto Liab | D13: Phys. Damage
A14: Premiums Written | B14: 0 | C14: 0 | D14: 0 | E14: =SUM(B14:D14) -> 0
A15: Policy Fees Written | B15: 0 | C15: 0 | D15: 0 | E15: =SUM(B15:D15) -> 0
A16: Premiums Collected | B16: 0 | C16: 0 | D16: 0 | E16: =SUM(B16:D16) -> 0
A17: Policy Fees Collected | B17: 0 | C17: 0 | D17: 0 | E17: =SUM(B17:D17) -> 0
A18: Premium Taxes | B18: =(B14+B15)*'Tax Rates'!$B$12 -> 0 | C18: =(C14+C15)*'Tax Rates'!$B$12 -> 0 | D18: =(D14+D15)*'Tax Rates'!$B$12 -> 0 | E18: =SUM(B18:D18) -> 0
A19: Losses Paid (Net of Salvage & Subrogation) | B19: 0 | C19: 0 | D19: 0 | E19: =SUM(B19:D19) -> 0
A20: Defense & Cost Containment Expenses Paid | B20: 0 | C20: 0 | D20: 0 | E20: =SUM(B20:D20) -> 0
A21: Adjusting & Other Expenses Paid | B21: 0 | C21: 0 | D21: 0 | E21: =SUM(B21:D21) -> 0
A22: Premium Earned - YTD | B22: 0 | C22: 0 | D22: 0 | E22: =SUM(B22:D22) -> 0
A23: Policy Fees Earned - YTD | B23: 0 | C23: 0 | D23: 0 | E23: =SUM(B23:D23) -> 0
A24: Unearned Premium Reserves | B24: 0 | C24: 0 | D24: 0 | E24: =SUM(B24:D24) -> 0
A25: Direct Losses Unpaid | B25: 0 | C25: 0 | D25: 0 | E25: =SUM(B25:D25) -> 0
A26: Defense & Cost Containment Unpaid | B26: 0 | C26: 0 | D26: 0 | E26: =SUM(B26:D26) -> 0
A27: Adjusting & Other Unpaid | B27: 0 | C27: 0 | D27: 0 | E27: =SUM(B27:D27) -> 0
A29: ='MTHLY-TOTAL'!A31 -> Submitted by: ______________

Sheet MTHLY-CT
A1: =+'Cash Settlement'!A2 -> COMPANY: SOUTHLAKE SPECIALTY INSURANCE COMPANY
A2: =+'Cash Settlement'!A1 -> PRODUCER: FUTURISTIC UNDERWRITERS LLC. | D2: Input area
A3: EXHIBIT OF PREMIUMS AND LOSSES
A4: FOR THE MONTH OF | C4: =+'Cash Settlement'!C9 -> 46142
A6: BY LINE, BY STATE
B11: 19.3 | C11: 19.4 | D11: 21.2
A12: =+'MTHLY-TOTAL'!A10 -> TREATY YEAR : 5/1/2020 | B12: Comm'l Auto | C12: Other Comm'l | D12: Comm'l Auto | E12: TOTALS
B13: No-Fault | C13: Auto Liab | D13: Phys. Damage
A14: Premiums Written | B14: 0 | C14: 0 | D14: 0 | E14: =SUM(B14:D14) -> 0
A15: Policy Fees Written | B15: 0 | C15: 0 | D15: 0 | E15: =SUM(B15:D15) -> 0
A16: Premiums Collected | B16: 0 | C16: 0 | D16: 0 | E16: =SUM(B16:D16) -> 0
A17: Policy Fees Collected | B17: 0 | C17: 0 | D17: 0 | E17: =SUM(B17:D17) -> 0
A18: Premium Taxes | B18: =(B14+B15)*'Tax Rates'!$B$13 -> 0 | C18: =(C14+C15)*'Tax Rates'!$B$13 -> 0 | D18: =(D14+D15)*'Tax Rates'!$B$13 -> 0 | E18: =SUM(B18:D18) -> 0
A19: Losses Paid (Net of Salvage & Subrogation) | B19: 0 | C19: 0 | D19: 0 | E19: =SUM(B19:D19) -> 0
A20: Defense & Cost Containment Expenses Paid | B20: 0 | C20: 0 | D20: 0 | E20: =SUM(B20:D20) -> 0
A21: Adjusting & Other Expenses Paid | B21: 0 | C21: 0 | D21: 0 | E21: =SUM(B21:D21) -> 0
A22: Premium Earned - YTD | B22: 0 | C22: 0 | D22: 0 | E22: =SUM(B22:D22) -> 0
A23: Policy Fees Earned - YTD | B23: 0 | C23: 0 | D23: 0 | E23: =SUM(B23:D23) -> 0
A24: Unearned Premium Reserves | B24: 0 | C24: 0 | D24: 0 | E24: =SUM(B24:D24) -> 0
A25: Direct Losses Unpaid | B25: 0 | C25: 0 | D25: 0 | E25: =SUM(B25:D25) -> 0
A26: Defense & Cost Containment Unpaid | B26: 0 | C26: 0 | D26: 0 | E26: =SUM(B26:D26) -> 0
A27: Adjusting & Other Unpaid | B27: 0 | C27: 0 | D27: 0 | E27: =SUM(B27:D27) -> 0
A29: ='MTHLY-TOTAL'!A31 -> Submitted by: ______________

Sheet MTHLY-DE
A1: =+'Cash Settlement'!A2 -> COMPANY: SOUTHLAKE SPECIALTY INSURANCE COMPANY
A2: =+'Cash Settlement'!A1 -> PRODUCER: FUTURISTIC UNDERWRITERS LLC. | D2: Input area
A3: EXHIBIT OF PREMIUMS AND LOSSES
A4: FOR THE MONTH OF | C4: =+'Cash Settlement'!C9 -> 46142
A6: BY LINE, BY STATE
B11: 19.3 | C11: 19.4 | D11: 21.2
A12: =+'MTHLY-TOTAL'!A10 -> TREATY YEAR : 5/1/2020 | B12: Comm'l Auto | C12: Other Comm'l | D12: Comm'l Auto | E12: TOTALS
B13: No-Fault | C13: Auto Liab | D13: Phys. Damage
A14: Premiums Written | B14: 0 | C14: 0 | D14: 0 | E14: =SUM(B14:D14) -> 0
A15: Policy Fees Written | B15: 0 | C15: 0 | D15: 0 | E15: =SUM(B15:D15) -> 0
A16: Premiums Collected | B16: 0 | C16: 0 | D16: 0 | E16: =SUM(B16:D16) -> 0
A17: Policy Fees Collected | B17: 0 | C17: 0 | D17: 0 | E17: =SUM(B17:D17) -> 0
A18: Premium Taxes | B18: =(B14+B15)*'Tax Rates'!$B$14 -> 0 | C18: =(C14+C15)*'Tax Rates'!$B$14 -> 0 | D18: =(D14+D15)*'Tax Rates'!$B$14 -> 0 | E18: =SUM(B18:D18) -> 0
A19: Losses Paid (Net of Salvage & Subrogation) | B19: 0 | C19: 0 | D19: 0 | E19: =SUM(B19:D19) -> 0
A20: Defense & Cost Containment Expenses Paid | B20: 0 | C20: 0 | D20: 0 | E20: =SUM(B20:D20) -> 0
A21: Adjusting & Other Expenses Paid | B21: 0 | C21: 0 | D21: 0 | E21: =SUM(B21:D21) -> 0
A22: Premium Earned - YTD | B22: 0 | C22: 0 | D22: 0 | E22: =SUM(B22:D22) -> 0
A23: Policy Fees Earned - YTD | B23: 0 | C23: 0 | D23: 0 | E23: =SUM(B23:D23) -> 0
A24: Unearned Premium Reserves | B24: 0 | C24: 0 | D24: 0 | E24: =SUM(B24:D24) -> 0
A25: Direct Losses Unpaid | B25: 0 | C25: 0 | D25: 0 | E25: =SUM(B25:D25) -> 0
A26: Defense & Cost Containment Unpaid | B26: 0 | C26: 0 | D26: 0 | E26: =SUM(B26:D26) -> 0
A27: Adjusting & Other Unpaid | B27: 0 | C27: 0 | D27: 0 | E27: =SUM(B27:D27) -> 0
A29: ='MTHLY-TOTAL'!A31 -> Submitted by: ______________

Sheet MTHLY-DC
A1: =+'Cash Settlement'!A2 -> COMPANY: SOUTHLAKE SPECIALTY INSURANCE COMPANY
A2: =+'Cash Settlement'!A1 -> PRODUCER: FUTURISTIC UNDERWRITERS LLC. | D2: Input area
A3: EXHIBIT OF PREMIUMS AND LOSSES
A4: FOR THE MONTH OF | C4: =+'Cash Settlement'!C9 -> 46142
A6: BY LINE, BY STATE
B11: 19.3 | C11: 19.4 | D11: 21.2
A12: =+'MTHLY-TOTAL'!A10 -> TREATY YEAR : 5/1/2020 | B12: Comm'l Auto | C12: Other Comm'l | D12: Comm'l Auto | E12: TOTALS
B13: No-Fault | C13: Auto Liab | D13: Phys. Damage
A14: Premiums Written | B14: 0 | C14: 0 | D14: 0 | E14: =SUM(B14:D14) -> 0
A15: Policy Fees Written | B15: 0 | C15: 0 | D15: 0 | E15: =SUM(B15:D15) -> 0
A16: Premiums Collected | B16: 0 | C16: 0 | D16: 0 | E16: =SUM(B16:D16) -> 0
A17: Policy Fees Collected | B17: 0 | C17: 0 | D17: 0 | E17: =SUM(B17:D17) -> 0
A18: Premium Taxes | B18: =(B14+B15)*'Tax Rates'!$B$15 -> 0 | C18: =(C14+C15)*'Tax Rates'!$B$15 -> 0 | D18: =(D14+D15)*'Tax Rates'!$B$15 -> 0 | E18: =SUM(B18:D18) -> 0
A19: Losses Paid (Net of Salvage & Subrogation) | B19: 0 | C19: 0 | D19: 0 | E19: =SUM(B19:D19) -> 0
A20: Defense & Cost Containment Expenses Paid | B20: 0 | C20: 0 | D20: 0 | E20: =SUM(B20:D20) -> 0
A21: Adjusting & Other Expenses Paid | B21: 0 | C21: 0 | D21: 0 | E21: =SUM(B21:D21) -> 0
A22: Premium Earned - YTD | B22: 0 | C22: 0 | D22: 0 | E22: =SUM(B22:D22) -> 0
A23: Policy Fees Earned - YTD | B23: 0 | C23: 0 | D23: 0 | E23: =SUM(B23:D23) -> 0
A24: Unearned Premium Reserves | B24: 0 | C24: 0 | D24: 0 | E24: =SUM(B24:D24) -> 0
A25: Direct Losses Unpaid | B25: 0 | C25: 0 | D25: 0 | E25: =SUM(B25:D25) -> 0
A26: Defense & Cost Containment Unpaid | B26: 0 | C26: 0 | D26: 0 | E26: =SUM(B26:D26) -> 0
A27: Adjusting & Other Unpaid | B27: 0 | C27: 0 | D27: 0 | E27: =SUM(B27:D27) -> 0
A29: ='MTHLY-TOTAL'!A31 -> Submitted by: ______________

Sheet MTHLY-FL
A1: =+'Cash Settlement'!A2 -> COMPANY: SOUTHLAKE SPECIALTY INSURANCE COMPANY
A2: =+'Cash Settlement'!A1 -> PRODUCER: FUTURISTIC UNDERWRITERS LLC. | D2: Input area
A3: EXHIBIT OF PREMIUMS AND LOSSES
A4: FOR THE MONTH OF | C4: =+'Cash Settlement'!C9 -> 46142
A6: BY LINE, BY STATE
B11: 19.3 | C11: 19.4 | D11: 21.2
A12: =+'MTHLY-TOTAL'!A10 -> TREATY YEAR : 5/1/2020 | B12: Comm'l Auto | C12: Other Comm'l | D12: Comm'l Auto | E12: TOTALS
B13: No-Fault | C13: Auto Liab | D13: Phys. Damage
A14: Premiums Written | B14: 0 | C14: 0 | D14: 0 | E14: =SUM(B14:D14) -> 0
A15: Policy Fees Written | B15: 0 | C15: 0 | D15: 0 | E15: =SUM(B15:D15) -> 0
A16: Premiums Collected | B16: 0 | C16: 0 | D16: 0 | E16: =SUM(B16:D16) -> 0
A17: Policy Fees Collected | B17: 0 | C17: 0 | D17: 0 | E17: =SUM(B17:D17) -> 0
A18: Premium Taxes | B18: =(B14+B15)*'Tax Rates'!$B$16 -> 0 | C18: =(C14+C15)*'Tax Rates'!$B$16 -> 0 | D18: =(D14+D15)*'Tax Rates'!$B$16 -> 0 | E18: =SUM(B18:D18) -> 0
A19: Losses Paid (Net of Salvage & Subrogation) | B19: 0 | C19: 0 | D19: 0 | E19: =SUM(B19:D19) -> 0
A20: Defense & Cost Containment Expenses Paid | B20: 0 | C20: 0 | D20: 0 | E20: =SUM(B20:D20) -> 0
A21: Adjusting & Other Expenses Paid | B21: 0 | C21: 0 | D21: 0 | E21: =SUM(B21:D21) -> 0
A22: Premium Earned - YTD | B22: 0 | C22: 0 | D22: 0 | E22: =SUM(B22:D22) -> 0
A23: Policy Fees Earned - YTD | B23: 0 | C23: 0 | D23: 0 | E23: =SUM(B23:D23) -> 0
A24: Unearned Premium Reserves | B24: 0 | C24: 0 | D24: 0 | E24: =SUM(B24:D24) -> 0
A25: Direct Losses Unpaid | B25: 0 | C25: 0 | D25: 0 | E25: =SUM(B25:D25) -> 0
A26: Defense & Cost Containment Unpaid | B26: 0 | C26: 0 | D26: 0 | E26: =SUM(B26:D26) -> 0
A27: Adjusting & Other Unpaid | B27: 0 | C27: 0 | D27: 0 | E27: =SUM(B27:D27) -> 0
A29: ='MTHLY-TOTAL'!A31 -> Submitted by: ______________

Sheet MTHLY-GA
A1: =+'Cash Settlement'!A2 -> COMPANY: SOUTHLAKE SPECIALTY INSURANCE COMPANY
A2: =+'Cash Settlement'!A1 -> PRODUCER: FUTURISTIC UNDERWRITERS LLC. | D2: Input area
A3: EXHIBIT OF PREMIUMS AND LOSSES
A4: FOR THE MONTH OF | C4: =+'Cash Settlement'!C9 -> 46142
A6: BY LINE, BY STATE
B11: 9 | C11: 19.4 | D11: 21.2
A12: =+'MTHLY-TOTAL'!A10 -> TREATY YEAR : 5/1/2020 | B12: Comm'l Auto | C12: Other Comm'l | D12: Comm'l Auto | E12: TOTALS
B13: Inland Marine | C13: Auto Liab | D13: Phys. Damage
A14: Premiums Written | B14: 0 | C14: 0 | D14: -1261.77 | E14: =SUM(B14:D14) -> -1261.77
A15: Policy Fees Written | B15: 0 | C15: 0 | D15: 0 | E15: =SUM(B15:D15) -> 0
A16: Premiums Collected | B16: 0 | C16: 0 | D16: -1261.77 | E16: =SUM(B16:D16) -> -1261.77
A17: Policy Fees Collected | B17: 0 | C17: 0 | D17: 0 | E17: =SUM(B17:D17) -> 0
A18: Premium Taxes | B18: =(B14+B15)*'Tax Rates'!$B$17 -> 0 | C18: =(C14+C15)*'Tax Rates'!$B$17 -> 0 | E18: =SUM(B18:D18) -> 0
A19: Losses Paid (Net of Salvage & Subrogation) | B19: 0 | C19: 0 | D19: 0 | E19: =SUM(B19:D19) -> 0
A20: Defense & Cost Containment Expenses Paid | B20: 0 | C20: 0 | D20: 0 | E20: =SUM(B20:D20) -> 0
A21: Adjusting & Other Expenses Paid | B21: 0 | C21: 0 | D21: -88.3239 | E21: =SUM(B21:D21) -> -88.3239
A22: Premium Earned - YTD | B22: 0 | C22: 0 | D22: 5669.34 | E22: =SUM(B22:D22) -> 5669.34
A23: Policy Fees Earned - YTD | B23: 0 | C23: 0 | D23: 0 | E23: =SUM(B23:D23) -> 0
A24: Unearned Premium Reserves | B24: 0 | C24: 0 | D24: 3466.11 | E24: =SUM(B24:D24) -> 3466.11
A25: Direct Losses Unpaid | B25: 0 | C25: 0 | D25: 0 | E25: =SUM(B25:D25) -> 0
A26: Defense & Cost Containment Unpaid | B26: 0 | C26: 0 | D26: 0 | E26: =SUM(B26:D26) -> 0
A27: Adjusting & Other Unpaid | B27: 0 | C27: 0 | D27: 0 | E27: =SUM(B27:D27) -> 0
A29: ='MTHLY-TOTAL'!A31 -> Submitted by: ______________

Sheet MTHLY-HI
A1: =+'Cash Settlement'!A2 -> COMPANY: SOUTHLAKE SPECIALTY INSURANCE COMPANY
A2: =+'Cash Settlement'!A1 -> PRODUCER: FUTURISTIC UNDERWRITERS LLC. | D2: Input area
A3: EXHIBIT OF PREMIUMS AND LOSSES
A4: FOR THE MONTH OF | C4: =+'Cash Settlement'!C9 -> 46142
A6: BY LINE, BY STATE
B11: 19.3 | C11: 19.4 | D11: 21.2
A12: =+'MTHLY-TOTAL'!A10 -> TREATY YEAR : 5/1/2020 | B12: Comm'l Auto | C12: Other Comm'l | D12: Comm'l Auto | E12: TOTALS
B13: No-Fault | C13: Auto Liab | D13: Phys. Damage
A14: Premiums Written | B14: 0 | C14: 0 | D14: 0 | E14: =SUM(B14:D14) -> 0
A15: Policy Fees Written | B15: 0 | C15: 0 | D15: 0 | E15: =SUM(B15:D15) -> 0
A16: Premiums Collected | B16: 0 | C16: 0 | D16: 0 | E16: =SUM(B16:D16) -> 0
A17: Policy Fees Collected | B17: 0 | C17: 0 | D17: 0 | E17: =SUM(B17:D17) -> 0
A18: Premium Taxes | B18: =(B14+B15)*'Tax Rates'!$B$18 -> 0 | C18: =(C14+C15)*'Tax Rates'!$B$18 -> 0 | D18: =(D14+D15)*'Tax Rates'!$B$18 -> 0 | E18: =SUM(B18:D18) -> 0
A19: Losses Paid (Net of Salvage & Subrogation) | B19: 0 | C19: 0 | D19: 0 | E19: =SUM(B19:D19) -> 0
A20: Defense & Cost Containment Expenses Paid | B20: 0 | C20: 0 | D20: 0 | E20: =SUM(B20:D20) -> 0
A21: Adjusting & Other Expenses Paid | B21: 0 | C21: 0 | D21: 0 | E21: =SUM(B21:D21) -> 0
A22: Premium Earned - YTD | B22: 0 | C22: 0 | D22: 0 | E22: =SUM(B22:D22) -> 0
A23: Policy Fees Earned - YTD | B23: 0 | C23: 0 | D23: 0 | E23: =SUM(B23:D23) -> 0
A24: Unearned Premium Reserves | B24: 0 | C24: 0 | D24: 0 | E24: =SUM(B24:D24) -> 0
A25: Direct Losses Unpaid | B25: 0 | C25: 0 | D25: 0 | E25: =SUM(B25:D25) -> 0
A26: Defense & Cost Containment Unpaid | B26: 0 | C26: 0 | D26: 0 | E26: =SUM(B26:D26) -> 0
A27: Adjusting & Other Unpaid | B27: 0 | C27: 0 | D27: 0 | E27: =SUM(B27:D27) -> 0
A29: ='MTHLY-TOTAL'!A31 -> Submitted by: ______________

Sheet MTHLY-IA
A1: =+'Cash Settlement'!A2 -> COMPANY: SOUTHLAKE SPECIALTY INSURANCE COMPANY
A2: =+'Cash Settlement'!A1 -> PRODUCER: FUTURISTIC UNDERWRITERS LLC. | D2: Input area
A3: EXHIBIT OF PREMIUMS AND LOSSES
A4: FOR THE MONTH OF | C4: =+'Cash Settlement'!C9 -> 46142
A6: BY LINE, BY STATE
B11: 19.3 | C11: 19.4 | D11: 21.2
A12: =+'MTHLY-TOTAL'!A10 -> TREATY YEAR : 5/1/2020 | B12: Comm'l Auto | C12: Other Comm'l | D12: Comm'l Auto | E12: TOTALS
B13: No-Fault | C13: Auto Liab | D13: Phys. Damage
A14: Premiums Written | B14: 0 | C14: 0 | D14: 0 | E14: =SUM(B14:D14) -> 0
A15: Policy Fees Written | B15: 0 | C15: 0 | D15: 0 | E15: =SUM(B15:D15) -> 0
A16: Premiums Collected | B16: 0 | C16: 0 | D16: 0 | E16: =SUM(B16:D16) -> 0
A17: Policy Fees Collected | B17: 0 | C17: 0 | D17: 0 | E17: =SUM(B17:D17) -> 0
A18: Premium Taxes | B18: =(B14+B15)*'Tax Rates'!$B$22 -> 0 | C18: =(C14+C15)*'Tax Rates'!$B$22 -> 0 | E18: =SUM(B18:D18) -> 0
A19: Losses Paid (Net of Salvage & Subrogation) | B19: 0 | C19: 0 | D19: 0 | E19: =SUM(B19:D19) -> 0
A20: Defense & Cost Containment Expenses Paid | B20: 0 | C20: 0 | D20: 0 | E20: =SUM(B20:D20) -> 0
A21: Adjusting & Other Expenses Paid | B21: 0 | C21: 0 | D21: 0 | E21: =SUM(B21:D21) -> 0
A22: Premium Earned - YTD | B22: 0 | C22: 0 | D22: 2347.66 | E22: =SUM(B22:D22) -> 2347.66
A23: Policy Fees Earned - YTD | B23: 0 | C23: 0 | D23: 0 | E23: =SUM(B23:D23) -> 0
A24: Unearned Premium Reserves | B24: 0 | C24: 0 | D24: 3006.98 | E24: =SUM(B24:D24) -> 3006.98
A25: Direct Losses Unpaid | B25: 0 | C25: 0 | D25: 0 | E25: =SUM(B25:D25) -> 0
A26: Defense & Cost Containment Unpaid | B26: 0 | C26: 0 | D26: 0 | E26: =SUM(B26:D26) -> 0
A27: Adjusting & Other Unpaid | B27: 0 | C27: 0 | D27: 0 | E27: =SUM(B27:D27) -> 0
A29: ='MTHLY-TOTAL'!A31 -> Submitted by: ______________

Sheet MTHLY-IL
A1: =+'Cash Settlement'!A2 -> COMPANY: SOUTHLAKE SPECIALTY INSURANCE COMPANY
A2: =+'Cash Settlement'!A1 -> PRODUCER: FUTURISTIC UNDERWRITERS LLC. | D2: Input area
A3: EXHIBIT OF PREMIUMS AND LOSSES
A4: FOR THE MONTH OF | C4: June-25
A6: BY LINE, BY STATE | C6: CA
B11: 19.3 | C11: 19.4 | D11: 21.2
A12: =+'MTHLY-TOTAL'!A10 -> TREATY YEAR : 5/1/2020 | B12: Comm'l Auto | C12: Other Comm'l | D12: Comm'l Auto | E12: TOTALS
B13: No-Fault | C13: Auto Liab | D13: Phys. Damage
A14: Premiums Written | B14: 0 | C14: 0 | D14: 0 | E14: =SUM(B14:D14) -> 0
A15: Policy Fees Written | B15: 0 | C15: 0 | D15: 0 | E15: =SUM(B15:D15) -> 0
A16: Premiums Collected | B16: 0 | C16: 0 | D16: 0 | E16: =SUM(B16:D16) -> 0
A17: Policy Fees Collected | B17: 0 | D17: 0 | E17: =SUM(B17:D17) -> 0
A18: Premium Taxes | B18: =(B14+B15)*'Tax Rates'!$B$20 -> 0 | D18: =(D14+D15)*'Tax Rates'!$B$20 -> 0 | E18: =SUM(B18:D18) -> 0
A19: Losses Paid (Net of Salvage & Subrogation) | B19: 0 | C19: 0 | D19: 0 | E19: =SUM(B19:D19) -> 0
A20: Defense & Cost Containment Expenses Paid | B20: 0 | C20: 0 | D20: 0 | E20: =SUM(B20:D20) -> 0
A21: Adjusting & Other Expenses Paid (ULAE) | B21: 0 | C21: 0 | D21: 0 | E21: =SUM(B21:D21) -> 0
A22: Premium Earned - YTD | B22: 0 | C22: 0 | D22: 0 | E22: =SUM(B22:D22) -> 0
A23: Policy Fees Earned - YTD | B23: 0 | C23: 0 | D23: 0 | E23: =SUM(B23:D23) -> 0
A24: Unearned Premium Reserves | B24: 0 | C24: 0 | D24: 0 | E24: =SUM(B24:D24) -> 0
A25: Direct Losses Unpaid | B25: 0 | C25: 0 | D25: 0 | E25: =SUM(B25:D25) -> 0
A26: Defense & Cost Containment Unpaid | B26: 0 | C26: 0 | D26: 0 | E26: =SUM(B26:D26) -> 0
A27: Adjusting & Other Unpaid | B27: 0 | D27: 0 | E27: =SUM(B27:D27) -> 0
C28: 0
A29: ='MTHLY-TOTAL'!A31 -> Submitted by: ______________

Sheet MTHLY-ID
A1: =+'Cash Settlement'!A2 -> COMPANY: SOUTHLAKE SPECIALTY INSURANCE COMPANY
A2: =+'Cash Settlement'!A1 -> PRODUCER: FUTURISTIC UNDERWRITERS LLC. | D2: Input area
A3: EXHIBIT OF PREMIUMS AND LOSSES
A4: FOR THE MONTH OF | C4: =+'Cash Settlement'!C9 -> 46142
A6: BY LINE, BY STATE
B11: 19.3 | C11: 19.4 | D11: 21.2
A12: =+'MTHLY-TOTAL'!A10 -> TREATY YEAR : 5/1/2020 | B12: Comm'l Auto | C12: Other Comm'l | D12: Comm'l Auto | E12: TOTALS
B13: No-Fault | C13: Auto Liab | D13: Phys. Damage
A14: Premiums Written | B14: 0 | C14: 0 | D14: 0 | E14: =SUM(B14:D14) -> 0
A15: Policy Fees Written | B15: 0 | C15: 0 | D15: 0 | E15: =SUM(B15:D15) -> 0
A16: Premiums Collected | B16: 0 | C16: 0 | D16: 0 | E16: =SUM(B16:D16) -> 0
A17: Policy Fees Collected | B17: 0 | C17: 0 | D17: 0 | E17: =SUM(B17:D17) -> 0
A18: Premium Taxes | B18: =(B14+B15)*'Tax Rates'!$B$19 -> 0 | C18: =(C14+C15)*'Tax Rates'!$B$19 -> 0 | D18: =(D14+D15)*'Tax Rates'!$B$19 -> 0 | E18: =SUM(B18:D18) -> 0
A19: Losses Paid (Net of Salvage & Subrogation) | B19: 0 | C19: 0 | D19: 0 | E19: =SUM(B19:D19) -> 0
A20: Defense & Cost Containment Expenses Paid | B20: 0 | C20: 0 | D20: 0 | E20: =SUM(B20:D20) -> 0
A21: Adjusting & Other Expenses Paid | B21: 0 | C21: 0 | D21: 0 | E21: =SUM(B21:D21) -> 0
A22: Premium Earned - YTD | B22: 0 | C22: 0 | D22: 0 | E22: =SUM(B22:D22) -> 0
A23: Policy Fees Earned - YTD | B23: 0 | C23: 0 | D23: 0 | E23: =SUM(B23:D23) -> 0
A24: Unearned Premium Reserves | B24: 0 | C24: 0 | D24: 0 | E24: =SUM(B24:D24) -> 0
A25: Direct Losses Unpaid | B25: 0 | C25: 0 | D25: 0 | E25: =SUM(B25:D25) -> 0
A26: Defense & Cost Containment Unpaid | B26: 0 | C26: 0 | D26: 0 | E26: =SUM(B26:D26) -> 0
A27: Adjusting & Other Unpaid | B27: 0 | C27: 0 | D27: 0 | E27: =SUM(B27:D27) -> 0
A29: ='MTHLY-TOTAL'!A31 -> Submitted by: ______________

Sheet MTHLY-IN
A1: =+'Cash Settlement'!A2 -> COMPANY: SOUTHLAKE SPECIALTY INSURANCE COMPANY
A2: =+'Cash Settlement'!A1 -> PRODUCER: FUTURISTIC UNDERWRITERS LLC. | D2: Input area
A3: EXHIBIT OF PREMIUMS AND LOSSES
A4: FOR THE MONTH OF | C4: =+'Cash Settlement'!C9 -> 46142
A6: BY LINE, BY STATE
B11: 9 | C11: 19.4 | D11: 21.2
A12: =+'MTHLY-TOTAL'!A10 -> TREATY YEAR : 5/1/2020 | B12: Comm'l Auto | C12: Other Comm'l | D12: Comm'l Auto | E12: TOTALS
B13: Inland Marine | C13: Auto Liab | D13: Phys. Damage
A14: Premiums Written | B14: 0 | C14: 0 | D14: 0 | E14: =SUM(B14:D14) -> 0
A15: Policy Fees Written | B15: 0 | C15: 0 | D15: 0 | E15: =SUM(B15:D15) -> 0
A16: Premiums Collected | B16: 0 | C16: 0 | D16: 0 | E16: =SUM(B16:D16) -> 0
A17: Policy Fees Collected | B17: 0 | C17: 0 | D17: 0 | E17: =SUM(B17:D17) -> 0
A18: Premium Taxes | B18: =(B14+B15)*'Tax Rates'!$B$21 -> 0 | C18: =(C14+C15)*'Tax Rates'!$B$21 -> 0 | E18: =SUM(B18:D18) -> 0
A19: Losses Paid (Net of Salvage & Subrogation) | B19: 0 | C19: 0 | D19: 57500 | E19: =SUM(B19:D19) -> 57500
A20: Defense & Cost Containment Expenses Paid | B20: 0 | C20: 0 | D20: 0 | E20: =SUM(B20:D20) -> 0
A21: Adjusting & Other Expenses Paid | B21: 0 | C21: 0 | D21: 0 | E21: =SUM(B21:D21) -> 0
A22: Premium Earned - YTD | B22: 0 | C22: 0 | D22: 21781.15 | E22: =SUM(B22:D22) -> 21781.15
A23: Policy Fees Earned - YTD | B23: 0 | C23: 0 | D23: 0 | E23: =SUM(B23:D23) -> 0
A24: Unearned Premium Reserves | B24: 0 | C24: 0 | D24: 25663.96 | E24: =SUM(B24:D24) -> 25663.96
A25: Direct Losses Unpaid | B25: 0 | C25: 0 | D25: 0 | E25: =SUM(B25:D25) -> 0
A26: Defense & Cost Containment Unpaid | B26: 0 | C26: 0 | D26: 0 | E26: =SUM(B26:D26) -> 0
A27: Adjusting & Other Unpaid | B27: 0 | C27: 0 | D27: 0 | E27: =SUM(B27:D27) -> 0
A29: ='MTHLY-TOTAL'!A31 -> Submitted by: ______________

Sheet MTHLY-KS
A1: =+'Cash Settlement'!A2 -> COMPANY: SOUTHLAKE SPECIALTY INSURANCE COMPANY
A2: =+'Cash Settlement'!A1 -> PRODUCER: FUTURISTIC UNDERWRITERS LLC. | D2: Input area
A3: EXHIBIT OF PREMIUMS AND LOSSES
A4: FOR THE MONTH OF | C4: =+'Cash Settlement'!C9 -> 46142
A6: BY LINE, BY STATE
B11: 19.3 | C11: 19.4 | D11: 21.2
A12: =+'MTHLY-TOTAL'!A10 -> TREATY YEAR : 5/1/2020 | B12: Comm'l Auto | C12: Other Comm'l | D12: Comm'l Auto | E12: TOTALS
B13: No-Fault | C13: Auto Liab | D13: Phys. Damage
A14: Premiums Written | B14: 0 | C14: 0 | D14: 0 | E14: =SUM(B14:D14) -> 0
A15: Policy Fees Written | B15: 0 | C15: 0 | D15: 0 | E15: =SUM(B15:D15) -> 0
A16: Premiums Collected | B16: 0 | C16: 0 | D16: 0 | E16: =SUM(B16:D16) -> 0
A17: Policy Fees Collected | B17: 0 | C17: 0 | D17: 0 | E17: =SUM(B17:D17) -> 0
A18: Premium Taxes | B18: =(B14+B15)*'Tax Rates'!$B$23 -> 0 | C18: =(C14+C15)*'Tax Rates'!$B$23 -> 0 | D18: =(D14+D15)*'Tax Rates'!$B$23 -> 0 | E18: =SUM(B18:D18) -> 0
A19: Losses Paid (Net of Salvage & Subrogation) | B19: 0 | C19: 0 | D19: 0 | E19: =SUM(B19:D19) -> 0
A20: Defense & Cost Containment Expenses Paid | B20: 0 | C20: 0 | D20: 0 | E20: =SUM(B20:D20) -> 0
A21: Adjusting & Other Expenses Paid | B21: 0 | C21: 0 | D21: 0 | E21: =SUM(B21:D21) -> 0
A22: Premium Earned - YTD | B22: 0 | C22: 0 | D22: 0 | E22: =SUM(B22:D22) -> 0
A23: Policy Fees Earned - YTD | B23: 0 | C23: 0 | D23: 0 | E23: =SUM(B23:D23) -> 0
A24: Unearned Premium Reserves | B24: 0 | C24: 0 | D24: 0 | E24: =SUM(B24:D24) -> 0
A25: Direct Losses Unpaid | B25: 0 | C25: 0 | D25: 0 | E25: =SUM(B25:D25) -> 0
A26: Defense & Cost Containment Unpaid | B26: 0 | C26: 0 | D26: 0 | E26: =SUM(B26:D26) -> 0
A27: Adjusting & Other Unpaid | B27: 0 | C27: 0 | D27: 0 | E27: =SUM(B27:D27) -> 0
A29: ='MTHLY-TOTAL'!A31 -> Submitted by: ______________

Sheet MTHLY-KY
A1: =+'Cash Settlement'!A2 -> COMPANY: SOUTHLAKE SPECIALTY INSURANCE COMPANY
A2: =+'Cash Settlement'!A1 -> PRODUCER: FUTURISTIC UNDERWRITERS LLC. | D2: Input area
A3: EXHIBIT OF PREMIUMS AND LOSSES
A4: FOR THE MONTH OF | C4: =+'Cash Settlement'!C9 -> 46142
A6: BY LINE, BY STATE
B11: 19.3 | C11: 19.4 | D11: 21.2
A12: =+'MTHLY-TOTAL'!A10 -> TREATY YEAR : 5/1/2020 | B12: Comm'l Auto | C12: Other Comm'l | D12: Comm'l Auto | E12: TOTALS
B13: No-Fault | C13: Auto Liab | D13: Phys. Damage
A14: Premiums Written | B14: 0 | C14: 0 | D14: 0 | E14: =SUM(B14:D14) -> 0
A15: Policy Fees Written | B15: 0 | C15: 0 | D15: 0 | E15: =SUM(B15:D15) -> 0
A16: Premiums Collected | B16: 0 | C16: 0 | D16: 0 | E16: =SUM(B16:D16) -> 0
A17: Policy Fees Collected | B17: 0 | C17: 0 | D17: 0 | E17: =SUM(B17:D17) -> 0
A18: Premium Taxes | B18: =(B14+B15)*'Tax Rates'!$B$24 -> 0 | C18: =(C14+C15)*'Tax Rates'!$B$24 -> 0 | D18: =(D14+D15)*'Tax Rates'!$B$24 -> 0 | E18: =SUM(B18:D18) -> 0
A19: Losses Paid (Net of Salvage & Subrogation) | B19: 0 | C19: 0 | D19: 0 | E19: =SUM(B19:D19) -> 0
A20: Defense & Cost Containment Expenses Paid | B20: 0 | C20: 0 | D20: 0 | E20: =SUM(B20:D20) -> 0
A21: Adjusting & Other Expenses Paid | B21: 0 | C21: 0 | D21: 0 | E21: =SUM(B21:D21) -> 0
A22: Premium Earned - YTD | B22: 0 | C22: 0 | D22: 0 | E22: =SUM(B22:D22) -> 0
A23: Policy Fees Earned - YTD | B23: 0 | C23: 0 | D23: 0 | E23: =SUM(B23:D23) -> 0
A24: Unearned Premium Reserves | B24: 0 | C24: 0 | D24: 0 | E24: =SUM(B24:D24) -> 0
A25: Direct Losses Unpaid | B25: 0 | C25: 0 | D25: 0 | E25: =SUM(B25:D25) -> 0
A26: Defense & Cost Containment Unpaid | B26: 0 | C26: 0 | D26: 0 | E26: =SUM(B26:D26) -> 0
A27: Adjusting & Other Unpaid | B27: 0 | C27: 0 | D27: 0 | E27: =SUM(B27:D27) -> 0
A29: ='MTHLY-TOTAL'!A31 -> Submitted by: ______________

Sheet MTHLY-LA
A1: =+'Cash Settlement'!A2 -> COMPANY: SOUTHLAKE SPECIALTY INSURANCE COMPANY
A2: =+'Cash Settlement'!A1 -> PRODUCER: FUTURISTIC UNDERWRITERS LLC. | D2: Input area
A3: EXHIBIT OF PREMIUMS AND LOSSES
A4: FOR THE MONTH OF | C4: =+'Cash Settlement'!C9 -> 46142
A6: BY LINE, BY STATE
B11: 19.3 | C11: 19.4 | D11: 21.2
A12: =+'MTHLY-TOTAL'!A10 -> TREATY YEAR : 5/1/2020 | B12: Comm'l Auto | C12: Other Comm'l | D12: Comm'l Auto | E12: TOTALS
B13: No-Fault | C13: Auto Liab | D13: Phys. Damage
A14: Premiums Written | B14: 0 | C14: 0 | D14: 0 | E14: =SUM(B14:D14) -> 0
A15: Policy Fees Written | B15: 0 | C15: 0 | D15: 0 | E15: =SUM(B15:D15) -> 0
A16: Premiums Collected | B16: 0 | C16: 0 | D16: 0 | E16: =SUM(B16:D16) -> 0
A17: Policy Fees Collected | B17: 0 | C17: 0 | D17: 0 | E17: =SUM(B17:D17) -> 0
A18: Premium Taxes | B18: =(B14+B15)*'Tax Rates'!$B$25 -> 0 | C18: =(C14+C15)*'Tax Rates'!$B$25 -> 0 | D18: =(D14+D15)*'Tax Rates'!$B$25 -> 0 | E18: =SUM(B18:D18) -> 0
A19: Losses Paid (Net of Salvage & Subrogation) | B19: 0 | C19: 0 | D19: 0 | E19: =SUM(B19:D19) -> 0
A20: Defense & Cost Containment Expenses Paid | B20: 0 | C20: 0 | D20: 0 | E20: =SUM(B20:D20) -> 0
A21: Adjusting & Other Expenses Paid | B21: 0 | C21: 0 | D21: 0 | E21: =SUM(B21:D21) -> 0
A22: Premium Earned - YTD | B22: 0 | C22: 0 | D22: 0 | E22: =SUM(B22:D22) -> 0
A23: Policy Fees Earned - YTD | B23: 0 | C23: 0 | D23: 0 | E23: =SUM(B23:D23) -> 0
A24: Unearned Premium Reserves | B24: 0 | C24: 0 | D24: 0 | E24: =SUM(B24:D24) -> 0
A25: Direct Losses Unpaid | B25: 0 | C25: 0 | D25: 0 | E25: =SUM(B25:D25) -> 0
A26: Defense & Cost Containment Unpaid | B26: 0 | C26: 0 | D26: 0 | E26: =SUM(B26:D26) -> 0
A27: Adjusting & Other Unpaid | B27: 0 | C27: 0 | D27: 0 | E27: =SUM(B27:D27) -> 0
A29: ='MTHLY-TOTAL'!A31 -> Submitted by: ______________

Sheet MTHLY-MA
A1: =+'Cash Settlement'!A2 -> COMPANY: SOUTHLAKE SPECIALTY INSURANCE COMPANY
A2: =+'Cash Settlement'!A1 -> PRODUCER: FUTURISTIC UNDERWRITERS LLC. | D2: Input area
A3: EXHIBIT OF PREMIUMS AND LOSSES
A4: FOR THE MONTH OF | C4: =+'Cash Settlement'!C9 -> 46142
A6: BY LINE, BY STATE
B11: 19.3 | C11: 19.4 | D11: 21.2
A12: =+'MTHLY-TOTAL'!A10 -> TREATY YEAR : 5/1/2020 | B12: Comm'l Auto | C12: Other Comm'l | D12: Comm'l Auto | E12: TOTALS
B13: No-Fault | C13: Auto Liab | D13: Phys. Damage
A14: Premiums Written | B14: 0 | C14: 0 | D14: 0 | E14: =SUM(B14:D14) -> 0
A15: Policy Fees Written | B15: 0 | C15: 0 | D15: 0 | E15: =SUM(B15:D15) -> 0
A16: Premiums Collected | B16: 0 | C16: 0 | D16: 0 | E16: =SUM(B16:D16) -> 0
A17: Policy Fees Collected | B17: 0 | C17: 0 | D17: 0 | E17: =SUM(B17:D17) -> 0
A18: Premium Taxes | B18: =(B14+B15)*'Tax Rates'!$B$28 -> 0 | C18: =(C14+C15)*'Tax Rates'!$B$28 -> 0 | D18: =(D14+D15)*'Tax Rates'!$B$28 -> 0 | E18: =SUM(B18:D18) -> 0
A19: Losses Paid (Net of Salvage & Subrogation) | B19: 0 | C19: 0 | D19: 0 | E19: =SUM(B19:D19) -> 0
A20: Defense & Cost Containment Expenses Paid | B20: 0 | C20: 0 | D20: 0 | E20: =SUM(B20:D20) -> 0
A21: Adjusting & Other Expenses Paid | B21: 0 | C21: 0 | D21: 0 | E21: =SUM(B21:D21) -> 0
A22: Premium Earned - YTD | B22: 0 | C22: 0 | D22: 0 | E22: =SUM(B22:D22) -> 0
A23: Policy Fees Earned - YTD | B23: 0 | C23: 0 | D23: 0 | E23: =SUM(B23:D23) -> 0
A24: Unearned Premium Reserves | B24: 0 | C24: 0 | D24: 0 | E24: =SUM(B24:D24) -> 0
A25: Direct Losses Unpaid | B25: 0 | C25: 0 | D25: 0 | E25: =SUM(B25:D25) -> 0
A26: Defense & Cost Containment Unpaid | B26: 0 | C26: 0 | D26: 0 | E26: =SUM(B26:D26) -> 0
A27: Adjusting & Other Unpaid | B27: 0 | C27: 0 | D27: 0 | E27: =SUM(B27:D27) -> 0
A29: ='MTHLY-TOTAL'!A31 -> Submitted by: ______________

Sheet MTHLY-MD
A1: =+'Cash Settlement'!A2 -> COMPANY: SOUTHLAKE SPECIALTY INSURANCE COMPANY
A2: =+'Cash Settlement'!A1 -> PRODUCER: FUTURISTIC UNDERWRITERS LLC. | D2: Input area
A3: EXHIBIT OF PREMIUMS AND LOSSES
A4: FOR THE MONTH OF | C4: =+'Cash Settlement'!C9 -> 46142
A6: BY LINE, BY STATE
B11: 19.3 | C11: 19.4 | D11: 21.2
A12: =+'MTHLY-TOTAL'!A10 -> TREATY YEAR : 5/1/2020 | B12: Comm'l Auto | C12: Other Comm'l | D12: Comm'l Auto | E12: TOTALS
B13: No-Fault | C13: Auto Liab | D13: Phys. Damage
A14: Premiums Written | B14: 0 | C14: 0 | D14: 0 | E14: =SUM(B14:D14) -> 0
A15: Policy Fees Written | B15: 0 | C15: 0 | D15: 0 | E15: =SUM(B15:D15) -> 0
A16: Premiums Collected | B16: 0 | C16: 0 | D16: 0 | E16: =SUM(B16:D16) -> 0
A17: Policy Fees Collected | B17: 0 | C17: 0 | D17: 0 | E17: =SUM(B17:D17) -> 0
A18: Premium Taxes | B18: =(B14+B15)*'Tax Rates'!$B$27 -> 0 | C18: =(C14+C15)*'Tax Rates'!$B$27 -> 0 | D18: =(D14+D15)*'Tax Rates'!$B$27 -> 0 | E18: =SUM(B18:D18) -> 0
A19: Losses Paid (Net of Salvage & Subrogation) | B19: 0 | C19: 0 | D19: 0 | E19: =SUM(B19:D19) -> 0
A20: Defense & Cost Containment Expenses Paid | B20: 0 | C20: 0 | D20: 0 | E20: =SUM(B20:D20) -> 0
A21: Adjusting & Other Expenses Paid | B21: 0 | C21: 0 | D21: 0 | E21: =SUM(B21:D21) -> 0
A22: Premium Earned - YTD | B22: 0 | C22: 0 | D22: 0 | E22: =SUM(B22:D22) -> 0
A23: Policy Fees Earned - YTD | B23: 0 | C23: 0 | D23: 0 | E23: =SUM(B23:D23) -> 0
A24: Unearned Premium Reserves | B24: 0 | C24: 0 | D24: 0 | E24: =SUM(B24:D24) -> 0
A25: Direct Losses Unpaid | B25: 0 | C25: 0 | D25: 0 | E25: =SUM(B25:D25) -> 0
A26: Defense & Cost Containment Unpaid | B26: 0 | C26: 0 | D26: 0 | E26: =SUM(B26:D26) -> 0
A27: Adjusting & Other Unpaid | B27: 0 | C27: 0 | D27: 0 | E27: =SUM(B27:D27) -> 0
A29: ='MTHLY-TOTAL'!A31 -> Submitted by: ______________

Sheet MTHLY-ME
A1: =+'Cash Settlement'!A2 -> COMPANY: SOUTHLAKE SPECIALTY INSURANCE COMPANY
A2: =+'Cash Settlement'!A1 -> PRODUCER: FUTURISTIC UNDERWRITERS LLC. | D2: Input area
A3: EXHIBIT OF PREMIUMS AND LOSSES
A4: FOR THE MONTH OF | C4: =+'Cash Settlement'!C9 -> 46142
A6: BY LINE, BY STATE
B11: 19.3 | C11: 19.4 | D11: 21.2
A12: =+'MTHLY-TOTAL'!A10 -> TREATY YEAR : 5/1/2020 | B12: Comm'l Auto | C12: Other Comm'l | D12: Comm'l Auto | E12: TOTALS
B13: No-Fault | C13: Auto Liab | D13: Phys. Damage
A14: Premiums Written | B14: 0 | C14: 0 | D14: 0 | E14: =SUM(B14:D14) -> 0
A15: Policy Fees Written | B15: 0 | C15: 0 | D15: 0 | E15: =SUM(B15:D15) -> 0
A16: Premiums Collected | B16: 0 | C16: 0 | D16: 0 | E16: =SUM(B16:D16) -> 0
A17: Policy Fees Collected | B17: 0 | C17: 0 | D17: 0 | E17: =SUM(B17:D17) -> 0
A18: Premium Taxes | B18: =(B14+B15)*'Tax Rates'!$B$26 -> 0 | C18: =(C14+C15)*'Tax Rates'!$B$26 -> 0 | D18: =(D14+D15)*'Tax Rates'!$B$26 -> 0 | E18: =SUM(B18:D18) -> 0
A19: Losses Paid (Net of Salvage & Subrogation) | B19: 0 | C19: 0 | D19: 0 | E19: =SUM(B19:D19) -> 0
A20: Defense & Cost Containment Expenses Paid | B20: 0 | C20: 0 | D20: 0 | E20: =SUM(B20:D20) -> 0
A21: Adjusting & Other Expenses Paid | B21: 0 | C21: 0 | D21: 0 | E21: =SUM(B21:D21) -> 0
A22: Premium Earned - YTD | B22: 0 | C22: 0 | D22: 0 | E22: =SUM(B22:D22) -> 0
A23: Policy Fees Earned - YTD | B23: 0 | C23: 0 | D23: 0 | E23: =SUM(B23:D23) -> 0
A24: Unearned Premium Reserves | B24: 0 | C24: 0 | D24: 0 | E24: =SUM(B24:D24) -> 0
A25: Direct Losses Unpaid | B25: 0 | C25: 0 | D25: 0 | E25: =SUM(B25:D25) -> 0
A26: Defense & Cost Containment Unpaid | B26: 0 | C26: 0 | D26: 0 | E26: =SUM(B26:D26) -> 0
A27: Adjusting & Other Unpaid | B27: 0 | C27: 0 | D27: 0 | E27: =SUM(B27:D27) -> 0
A29: ='MTHLY-TOTAL'!A31 -> Submitted by: ______________

Sheet MTHLY-MI
A1: =+'Cash Settlement'!A2 -> COMPANY: SOUTHLAKE SPECIALTY INSURANCE COMPANY
A2: =+'Cash Settlement'!A1 -> PRODUCER: FUTURISTIC UNDERWRITERS LLC. | D2: Input area
A3: EXHIBIT OF PREMIUMS AND LOSSES
A4: FOR THE MONTH OF | C4: =+'Cash Settlement'!C9 -> 46142
A6: BY LINE, BY STATE
B11: 9 | C11: 19.4 | D11: 21.2
A12: =+'MTHLY-TOTAL'!A10 -> TREATY YEAR : 5/1/2020 | B12: Comm'l Auto | C12: Other Comm'l | D12: Comm'l Auto | E12: TOTALS
B13: Inland Marine | C13: Auto Liab | D13: Phys. Damage
A14: Premiums Written | B14: 0 | C14: 0 | D14: 0 | E14: =SUM(B14:D14) -> 0
A15: Policy Fees Written | B15: 0 | C15: 0 | D15: 0 | E15: =SUM(B15:D15) -> 0
A16: Premiums Collected | B16: 0 | C16: 0 | D16: 0 | E16: =SUM(B16:D16) -> 0
A17: Policy Fees Collected | B17: 0 | C17: 0 | D17: 0 | E17: =SUM(B17:D17) -> 0
A18: Premium Taxes | B18: =(B14+B15)*'Tax Rates'!$B$29 -> 0 | C18: =(C14+C15)*'Tax Rates'!$B$29 -> 0 | E18: =SUM(B18:D18) -> 0
A19: Losses Paid (Net of Salvage & Subrogation) | B19: 0 | C19: 0 | D19: 0 | E19: =SUM(B19:D19) -> 0
A20: Defense & Cost Containment Expenses Paid | B20: 0 | C20: 0 | D20: 0 | E20: =SUM(B20:D20) -> 0
A21: Adjusting & Other Expenses Paid | B21: 0 | C21: 0 | D21: 0 | E21: =SUM(B21:D21) -> 0
A22: Premium Earned - YTD | B22: 0 | C22: 0 | D22: 18270.37 | E22: =SUM(B22:D22) -> 18270.37
A23: Policy Fees Earned - YTD | B23: 0 | C23: 0 | D23: 0 | E23: =SUM(B23:D23) -> 0
A24: Unearned Premium Reserves | B24: 0 | C24: 0 | D24: 2775.66 | E24: =SUM(B24:D24) -> 2775.66
A25: Direct Losses Unpaid | B25: 0 | C25: 0 | D25: 0 | E25: =SUM(B25:D25) -> 0
A26: Defense & Cost Containment Unpaid | B26: 0 | C26: 0 | D26: 0 | E26: =SUM(B26:D26) -> 0
A27: Adjusting & Other Unpaid | B27: 0 | C27: 0 | D27: 0 | E27: =SUM(B27:D27) -> 0
A29: ='MTHLY-TOTAL'!A31 -> Submitted by: ______________

Sheet MTHLY-MN
A1: =+'Cash Settlement'!A2 -> COMPANY: SOUTHLAKE SPECIALTY INSURANCE COMPANY
A2: =+'Cash Settlement'!A1 -> PRODUCER: FUTURISTIC UNDERWRITERS LLC. | D2: Input area
A3: EXHIBIT OF PREMIUMS AND LOSSES
A4: FOR THE MONTH OF | C4: =+'Cash Settlement'!C9 -> 46142
A6: BY LINE, BY STATE
B11: 19.3 | C11: 19.4 | D11: 21.2
A12: =+'MTHLY-TOTAL'!A10 -> TREATY YEAR : 5/1/2020 | B12: Comm'l Auto | C12: Other Comm'l | D12: Comm'l Auto | E12: TOTALS
B13: No-Fault | C13: Auto Liab | D13: Phys. Damage
A14: Premiums Written | B14: 0 | C14: 0 | D14: 0 | E14: =SUM(B14:D14) -> 0
A15: Policy Fees Written | B15: 0 | C15: 0 | D15: 0 | E15: =SUM(B15:D15) -> 0
A16: Premiums Collected | B16: 0 | C16: 0 | D16: 0 | E16: =SUM(B16:D16) -> 0
A17: Policy Fees Collected | B17: 0 | C17: 0 | D17: 0 | E17: =SUM(B17:D17) -> 0
A18: Premium Taxes | B18: =(B14+B15)*'Tax Rates'!$B$30 -> 0 | C18: =(C14+C15)*'Tax Rates'!$B$30 -> 0 | E18: =SUM(B18:D18) -> 0
A19: Losses Paid (Net of Salvage & Subrogation) | B19: 0 | C19: 0 | D19: 0 | E19: =SUM(B19:D19) -> 0
A20: Defense & Cost Containment Expenses Paid | B20: 0 | C20: 0 | D20: 0 | E20: =SUM(B20:D20) -> 0
A21: Adjusting & Other Expenses Paid | B21: 0 | C21: 0 | D21: 0 | E21: =SUM(B21:D21) -> 0
A22: Premium Earned - YTD | B22: 0 | C22: 0 | D22: 16329.93 | E22: =SUM(B22:D22) -> 16329.93
A23: Policy Fees Earned - YTD | B23: 0 | C23: 0 | D23: 0 | E23: =SUM(B23:D23) -> 0
A24: Unearned Premium Reserves | B24: 0 | C24: 0 | D24: 12758.8 | E24: =SUM(B24:D24) -> 12758.8
A25: Direct Losses Unpaid | B25: 0 | C25: 0 | D25: 0 | E25: =SUM(B25:D25) -> 0
A26: Defense & Cost Containment Unpaid | B26: 0 | C26: 0 | D26: 0 | E26: =SUM(B26:D26) -> 0
A27: Adjusting & Other Unpaid | B27: 0 | C27: 0 | D27: 0 | E27: =SUM(B27:D27) -> 0
A29: ='MTHLY-TOTAL'!A31 -> Submitted by: ______________

Sheet MTHLY-MO
A1: =+'Cash Settlement'!A2 -> COMPANY: SOUTHLAKE SPECIALTY INSURANCE COMPANY
A2: =+'Cash Settlement'!A1 -> PRODUCER: FUTURISTIC UNDERWRITERS LLC. | D2: Input area
A3: EXHIBIT OF PREMIUMS AND LOSSES
A4: FOR THE MONTH OF | C4: =+'Cash Settlement'!C9 -> 46142
A6: BY LINE, BY STATE
B11: 19.3 | C11: 19.4 | D11: 21.2
A12: =+'MTHLY-TOTAL'!A10 -> TREATY YEAR : 5/1/2020 | B12: Comm'l Auto | C12: Other Comm'l | D12: Comm'l Auto | E12: TOTALS
B13: No-Fault | C13: Auto Liab | D13: Phys. Damage
A14: Premiums Written | B14: 0 | C14: 0 | D14: 0 | E14: =SUM(B14:D14) -> 0
A15: Policy Fees Written | B15: 0 | C15: 0 | D15: 0 | E15: =SUM(B15:D15) -> 0
