Workbook

Sheet Starlight APD
A1: Southlake Specialty Insurance Company
C2: 2025 | P2: 2026
C3: ITD | P3: YTD | Q3: ITD | R3: System | T3: Summary
B4: FUT Starlight APD DRP T2 - Total | C4: Totals | D4: Jan-26 | E4: Feb-26 | F4: Mar-26 | G4: Apr-26 | H4: May-26 | I4: Jun-26 | J4: Jul-26 | K4: Aug-26 | L4: Sep-26 | M4: Oct-26 | N4: Nov-26 | O4: Dec-26 | P4: Totals | Q4: Totals | R4: Reports | S4: Variance | T4: Account Description | U4: Comp | V4: Account | W4: CC | X4: MGA | Y4: LOB | Z4: ST | AA4: EXT | AB4: Sub | AC4: Description | AD4: Jan-26 | AE4: Feb-26 | AF4: Mar-26 | AG4: Apr-26 | AH4: May-26 | AI4: Jun-26 | AJ4: Jul-26 | AK4: Aug-26 | AL4: Sep-26 | AM4: Oct-26 | AN4: Nov-26 | AO4: Dec-26 | AP4: Totals
T5: Uncollected Premium Direct | U5: 100 | V5: 120100 | W5: 00 | X5: 2002 | Y5: 000212 | Z5: 00 | AA5: 0000 | AC5: FUT Starlight T2 APD DRP | AD5: =SUM(AL:WY!AE5) -> -4003.16 | AE5: =SUM(AL:WY!AP5) -> -32023.47 | AF5: =SUM(AL:WY!BA5) -> -8507.36 | AG5: =SUM(AL:WY!BL5) -> 0 | AH5: =SUM(AL:WY!BW5) -> 0 | AI5: =SUM(AL:WY!CH5) -> 0 | AJ5: =SUM(AL:WY!CS5) -> 0 | AK5: =SUM(AL:WY!DD5) -> 0 | AL5: =SUM(AL:WY!DO5) -> 0 | AM5: =SUM(AL:WY!DZ5) -> 0 | AN5: =SUM(AL:WY!EK5) -> 0 | AO5: =SUM(AL:WY!EV5) -> 0 | AP5: =SUM(AD5:AO5) -> -44533.99
A6: a. | B6: Premiums Written | C6: =SUM(AL:WY!C6) -> 2135589.9 | D6: =SUM(AL:WY!D6) -> -4003.16 | E6: =SUM(AL:WY!E6) -> -32023.47 | F6: =SUM(AL:WY!F6) -> -8507.36 | G6: =SUM(AL:WY!G6) -> 0 | H6: =SUM(AL:WY!H6) -> 0 | I6: =SUM(AL:WY!I6) -> 0 | J6: =SUM(AL:WY!J6) -> 0 | ... O6: =SUM(AL:WY!O6) -> 0 | P6: =SUM(D6:O6) -> -44533.99 | Q6: =+C6+P6 -> 2091055.9 | R6: =SUM(AL:WY!R6) -> 2072670.7 | S6: =Q6-R6 -> 18385.17 | T6: Direct Premium Written | U6: 100 | V6: 400100 | W6: 00 | X6: 2002 | Y6: 000212 | Z6: CA | AA6: 0000 | AC6: FUT Starlight T2 APD DRP | AD6: =SUM(AL:WY!AE6) -> 4003.16 | AE6: =SUM(AL:WY!AP6) -> 32023.47 | AF6: =SUM(AL:WY!BA6) -> 8507.36 | AG6: =SUM(AL:WY!BL6) -> 0 | AH6: =SUM(AL:WY!BW6) -> 0 | AI6: =SUM(AL:WY!CH6) -> 0 | AJ6: =SUM(AL:WY!CS6) -> 0 | AK6: =SUM(AL:WY!DD6) -> 0 | AL6: =SUM(AL:WY!DO6) -> 0 | AM6: =SUM(AL:WY!DZ6) -> 0 | AN6: =SUM(AL:WY!EK6) -> 0 | AO6: =SUM(AL:WY!EV6) -> 0 | AP6: =SUM(AD6:AO6) -> 44533.99
B7: Change in UEP | C7: =SUM(AL:WY!C7) -> -1641729.9 | D7: =SUM(AL:WY!D7) -> 182408.02 | E7: =SUM(AL:WY!E7) -> 208703.25 | F7: =SUM(AL:WY!F7) -> 182754.37 | G7: =SUM(AL:WY!G7) -> 0 | H7: =SUM(AL:WY!H7) -> 0 | I7: =SUM(AL:WY!I7) -> 0 | J7: =SUM(AL:WY!J7) -> 0 | ... O7: =SUM(AL:WY!O7) -> 0 | P7: =SUM(D7:O7) -> 573865.64 | Q7: =+C7+P7 -> -1067864.3 | R7: =SUM(AL:WY!R7) -> -1067864.3 | S7: =Q7-R7 -> 0 | T7: Change in Unearned Premium Direct | U7: 100 | V7: 411100 | W7: 00 | X7: 2002 | Y7: 000212 | Z7: CA | AA7: 0000 | AC7: FUT Starlight T2 APD DRP | AD7: =SUM(AL:WY!AE7) -> -182408.02 | AE7: =SUM(AL:WY!AP7) -> -208703.25 | AF7: =SUM(AL:WY!BA7) -> -182754.37 | AG7: =SUM(AL:WY!BL7) -> 0 | AH7: =SUM(AL:WY!BW7) -> 0 | AI7: =SUM(AL:WY!CH7) -> 0 | AJ7: =SUM(AL:WY!CS7) -> 0 | AK7: =SUM(AL:WY!DD7) -> 0 | AL7: =SUM(AL:WY!DO7) -> 0 | AM7: =SUM(AL:WY!DZ7) -> 0 | AN7: =SUM(AL:WY!EK7) -> 0 | AO7: =SUM(AL:WY!EV7) -> 0 | AP7: =SUM(AD7:AO7) -> -573865.64
B8: Premiums Earned | C8: =SUM(C6:C7) -> 493859.97 | D8: =SUM(D6:D7) -> 178404.86 | E8: =SUM(E6:E7) -> 176679.78 | F8: =SUM(F6:F7) -> 174247.01 | G8: =SUM(G6:G7) -> 0 | H8: =SUM(H6:H7) -> 0 | I8: =SUM(I6:I7) -> 0 | J8: =SUM(J6:J7) -> 0 | ... S8: =SUM(S6:S7) -> 18385.17 | T8: Unearned Premium Direct | U8: 100 | V8: 230100 | W8: 00 | X8: 2002 | Y8: 000212 | Z8: CA | AA8: 0000 | AC8: FUT Starlight T2 APD DRP | AD8: =SUM(AL:WY!AE8) -> 182408.02 | AE8: =SUM(AL:WY!AP8) -> 208703.25 | AF8: =SUM(AL:WY!BA8) -> 182754.37 | AG8: =SUM(AL:WY!BL8) -> 0 | AH8: =SUM(AL:WY!BW8) -> 0 | AI8: =SUM(AL:WY!CH8) -> 0 | AJ8: =SUM(AL:WY!CS8) -> 0 | AK8: =SUM(AL:WY!DD8) -> 0 | AL8: =SUM(AL:WY!DO8) -> 0 | AM8: =SUM(AL:WY!DZ8) -> 0 | AN8: =SUM(AL:WY!EK8) -> 0 | AO8: =SUM(AL:WY!EV8) -> 0 | AP8: =SUM(AD8:AO8) -> 573865.64
T9: Ceded Premium Written | U9: 100 | V9: 400300 | W9: 00 | X9: 2002 | Y9: 000212 | Z9: 00 | AA9: 0000 | AC9: FUT Starlight T2 APD DRP | AD9: =SUM(AL:WY!AE9) -> -4003.16 | AE9: =SUM(AL:WY!AP9) -> -32023.47 | AF9: =SUM(AL:WY!BA9) -> -8507.36 | AG9: =SUM(AL:WY!BL9) -> 0 | AH9: =SUM(AL:WY!BW9) -> 0 | AI9: =SUM(AL:WY!CH9) -> 0 | AJ9: =SUM(AL:WY!CS9) -> 0 | AK9: =SUM(AL:WY!DD9) -> 0 | AL9: =SUM(AL:WY!DO9) -> 0 | AM9: =SUM(AL:WY!DZ9) -> 0 | AN9: =SUM(AL:WY!EK9) -> 0 | AO9: =SUM(AL:WY!EV9) -> 0 | AP9: =SUM(AD9:AO9) -> -44533.99
B10: Less: | T10: Ceded Reinsurance Premiums Payable | U10: 100 | V10: 243100 | W10: 00 | X10: 2002 | Y10: 000212 | Z10: 00 | AA10: 0000 | AC10: FUT Starlight T2 APD DRP | AD10: =SUM(AL:WY!AE10) -> 4003.16 | AE10: =SUM(AL:WY!AP10) -> 32023.47 | AF10: =SUM(AL:WY!BA10) -> 8507.36 | AG10: =SUM(AL:WY!BL10) -> 0 | AH10: =SUM(AL:WY!BW10) -> 0 | AI10: =SUM(AL:WY!CH10) -> 0 | AJ10: =SUM(AL:WY!CS10) -> 0 | AK10: =SUM(AL:WY!DD10) -> 0 | AL10: =SUM(AL:WY!DO10) -> 0 | AM10: =SUM(AL:WY!DZ10) -> 0 | AN10: =SUM(AL:WY!EK10) -> 0 | AO10: =SUM(AL:WY!EV10) -> 0 | AP10: =SUM(AD10:AO10) -> 44533.99
A11: b. | B11: Ceding Commissions at 29% | C11: =SUM(AL:WY!C11) -> 619321.06 | D11: =SUM(AL:WY!D11) -> -1160.9164 | E11: =SUM(AL:WY!E11) -> -9286.8063 | F11: =SUM(AL:WY!F11) -> -2467.1344 | G11: =SUM(AL:WY!G11) -> 0 | H11: =SUM(AL:WY!H11) -> 0 | I11: =SUM(AL:WY!I11) -> 0 | J11: =SUM(AL:WY!J11) -> 0 | ... O11: =SUM(AL:WY!O11) -> 0 | P11: =SUM(D11:O11) -> -12914.857 | Q11: =+C11+P11 -> 606406.21 | T11: Unearned Premium Ceded | U11: 100 | V11: 230300 | W11: 00 | X11: 2002 | Y11: 000212 | Z11: 00 | AA11: 0000 | AC11: FUT Starlight T2 APD DRP | AD11: =SUM(AL:WY!AE11) -> -182408.02 | AE11: =SUM(AL:WY!AP11) -> -208703.25 | AF11: =SUM(AL:WY!BA11) -> -182754.37 | AG11: =SUM(AL:WY!BL11) -> 0 | AH11: =SUM(AL:WY!BW11) -> 0 | AI11: =SUM(AL:WY!CH11) -> 0 | AJ11: =SUM(AL:WY!CS11) -> 0 | AK11: =SUM(AL:WY!DD11) -> 0 | AL11: =SUM(AL:WY!DO11) -> 0 | AM11: =SUM(AL:WY!DZ11) -> 0 | AN11: =SUM(AL:WY!EK11) -> 0 | AO11: =SUM(AL:WY!EV11) -> 0 | AP11: =SUM(AD11:AO11) -> -573865.64
B12: Ceding Commissions on UEP | C12: =SUM(AL:WY!C12) -> 0 | D12: =SUM(AL:WY!D12) -> 0 | E12: =SUM(AL:WY!E12) -> 0 | F12: =SUM(AL:WY!F12) -> 0 | G12: =SUM(AL:WY!G12) -> 0 | H12: =SUM(AL:WY!H12) -> 0 | I12: =SUM(AL:WY!I12) -> 0 | J12: =SUM(AL:WY!J12) -> 0 | ... O12: =SUM(AL:WY!O12) -> 0 | P12: =SUM(D12:O12) -> 0 | Q12: =+C12+P12 -> 0 | T12: Change in Unearned Premium Ceded | U12: 100 | V12: 411300 | W12: 00 | X12: 2002 | Y12: 000212 | Z12: 00 | AA12: 0000 | AC12: FUT Starlight T2 APD DRP | AD12: =SUM(AL:WY!AE12) -> 182408.02 | AE12: =SUM(AL:WY!AP12) -> 208703.25 | AF12: =SUM(AL:WY!BA12) -> 182754.37 | AG12: =SUM(AL:WY!BL12) -> 0 | AH12: =SUM(AL:WY!BW12) -> 0 | AI12: =SUM(AL:WY!CH12) -> 0 | AJ12: =SUM(AL:WY!CS12) -> 0 | AK12: =SUM(AL:WY!DD12) -> 0 | AL12: =SUM(AL:WY!DO12) -> 0 | AM12: =SUM(AL:WY!DZ12) -> 0 | AN12: =SUM(AL:WY!EK12) -> 0 | AO12: =SUM(AL:WY!EV12) -> 0 | AP12: =SUM(AD12:AO12) -> 573865.64
B13: Ceding Commissions Earned | C13: =SUM(C11:C12) -> 619321.06 | D13: =SUM(D11:D12) -> -1160.9164 | E13: =SUM(E11:E12) -> -9286.8063 | F13: =SUM(F11:F12) -> -2467.1344 | G13: =SUM(G11:G12) -> 0 | H13: =SUM(H11:H12) -> 0 | I13: =SUM(I11:I12) -> 0 | J13: =SUM(J11:J12) -> 0 | ... Q13: =SUM(Q11:Q12) -> 606406.21 | T13: Commissions Direct | U13: 100 | V13: 500100 | W13: 00 | X13: 2002 | Y13: 000212 | Z13: CA | AA13: 0000 | AC13: FUT Starlight T2 APD DRP | AD13: =SUM(AL:WY!AE13) -> -1160.9164 | AE13: =SUM(AL:WY!AP13) -> -9286.8063 | AF13: =SUM(AL:WY!BA13) -> -2467.1344 | AG13: =SUM(AL:WY!BL13) -> 0 | AH13: =SUM(AL:WY!BW13) -> 0 | AI13: =SUM(AL:WY!CH13) -> 0 | AJ13: =SUM(AL:WY!CS13) -> 0 | AK13: =SUM(AL:WY!DD13) -> 0 | AL13: =SUM(AL:WY!DO13) -> 0 | AM13: =SUM(AL:WY!DZ13) -> 0 | AN13: =SUM(AL:WY!EK13) -> 0 | AO13: =SUM(AL:WY!EV13) -> 0 | AP13: =SUM(AD13:AO13) -> -12914.857
D14: =+D6-D11 -> -2842.2436 | E14: =+E6-E11 -> -22736.664 | F14: =+F6-F11 -> -6040.2256 | G14: =+G6-G11 -> 0 | H14: =+H6-H11 -> 0 | I14: =+I6-I11 -> 0 | J14: =+J6-J11 -> 0 | K14: =+K6-K11 -> 0 | ... O14: =+O6-O11 -> 0 | T14: Uncollected Premium Direct | U14: 100 | V14: 120100 | W14: 00 | X14: 2002 | Y14: 000212 | Z14: 00 | AA14: 0000 | AC14: FUT Starlight T2 APD DRP | AD14: =SUM(AL:WY!AE14) -> 1160.9164 | AE14: =SUM(AL:WY!AP14) -> 9286.8063 | AF14: =SUM(AL:WY!BA14) -> 2467.1344 | AG14: =SUM(AL:WY!BL14) -> 0 | AH14: =SUM(AL:WY!BW14) -> 0 | AI14: =SUM(AL:WY!CH14) -> 0 | AJ14: =SUM(AL:WY!CS14) -> 0 | AK14: =SUM(AL:WY!DD14) -> 0 | AL14: =SUM(AL:WY!DO14) -> 0 | AM14: =SUM(AL:WY!DZ14) -> 0 | AN14: =SUM(AL:WY!EK14) -> 0 | AO14: =SUM(AL:WY!EV14) -> 0 | AP14: =SUM(AD14:AO14) -> 12914.857
A15: c. | B15: Losses Paid (net of salvage & subro) | C15: =SUM(AL:WY!C15) -> 21210.31 | D15: =SUM(AL:WY!D15) -> 12500 | E15: =SUM(AL:WY!E15) -> 21996.52 | F15: =SUM(AL:WY!F15) -> 103850.88 | G15: =SUM(AL:WY!G15) -> 0 | H15: =SUM(AL:WY!H15) -> 0 | I15: =SUM(AL:WY!I15) -> 0 | J15: =SUM(AL:WY!J15) -> 0 | ... O15: =SUM(AL:WY!O15) -> 0 | P15: =SUM(D15:O15) -> 138347.4 | Q15: =+C15+P15 -> 159557.71 | R15: =SUM(AL:WY!R15) -> 159557.71 | S15: =Q15-R15 -> 0 | T15: Ceded Reinsurance Premiums Payable | U15: 100 | V15: 243100 | W15: 00 | X15: 2002 | Y15: 000212 | Z15: 00 | AA15: 0000 | AC15: FUT Starlight T2 APD DRP | AD15: =SUM(AL:WY!AE15) -> -1160.9164 | AE15: =SUM(AL:WY!AP15) -> -9286.8063 | AF15: =SUM(AL:WY!BA15) -> -2467.1344 | AG15: =SUM(AL:WY!BL15) -> 0 | AH15: =SUM(AL:WY!BW15) -> 0 | AI15: =SUM(AL:WY!CH15) -> 0 | AJ15: =SUM(AL:WY!CS15) -> 0 | AK15: =SUM(AL:WY!DD15) -> 0 | AL15: =SUM(AL:WY!DO15) -> 0 | AM15: =SUM(AL:WY!DZ15) -> 0 | AN15: =SUM(AL:WY!EK15) -> 0 | AO15: =SUM(AL:WY!EV15) -> 0 | AP15: =SUM(AD15:AO15) -> -12914.857
B16: Change in Loss Reserves | C16: =SUM(AL:WY!C16) -> 25000 | D16: =SUM(AL:WY!D16) -> 60564 | E16: =SUM(AL:WY!E16) -> 13600.51 | F16: =SUM(AL:WY!F16) -> 152500 | G16: =SUM(AL:WY!G16) -> 0 | H16: =SUM(AL:WY!H16) -> 0 | I16: =SUM(AL:WY!I16) -> 0 | J16: =SUM(AL:WY!J16) -> 0 | ... O16: =SUM(AL:WY!O16) -> 0 | P16: =SUM(D16:O16) -> 226664.51 | Q16: =+C16+P16 -> 251664.51 | T16: Commissions Ceded | U16: 100 | V16: 500300 | W16: 00 | X16: 2002 | Y16: 000212 | Z16: CA | AA16: 0000 | AC16: FUT Starlight T2 APD DRP | AD16: =SUM(AL:WY!AE16) -> 1160.9164 | AE16: =SUM(AL:WY!AP16) -> 9286.8063 | AF16: =SUM(AL:WY!BA16) -> 2467.1344 | AG16: =SUM(AL:WY!BL16) -> 0 | AH16: =SUM(AL:WY!BW16) -> 0 | AI16: =SUM(AL:WY!CH16) -> 0 | AJ16: =SUM(AL:WY!CS16) -> 0 | AK16: =SUM(AL:WY!DD16) -> 0 | AL16: =SUM(AL:WY!DO16) -> 0 | AM16: =SUM(AL:WY!DZ16) -> 0 | AN16: =SUM(AL:WY!EK16) -> 0 | AO16: =SUM(AL:WY!EV16) -> 0 | AP16: =SUM(AD16:AO16) -> 12914.857
B17: Change in Loss IBNR Reserves | C17: =SUM(AL:WY!C17) -> 233314.43 | D17: =SUM(AL:WY!D17) -> 27913.151 | E17: =SUM(AL:WY!E17) -> 64403.725 | F17: =SUM(AL:WY!F17) -> -157727.07 | G17: =SUM(AL:WY!G17) -> 0 | H17: =SUM(AL:WY!H17) -> 0 | I17: =SUM(AL:WY!I17) -> 0 | J17: =SUM(AL:WY!J17) -> 0 | ... O17: =SUM(AL:WY!O17) -> 0 | P17: =SUM(D17:O17) -> -65410.196 | Q17: =+C17+P17 -> 167904.24 | T17: Direct Losses paid | U17: 100 | V17: 600100 | W17: 00 | X17: 2002 | Y17: 000212 | Z17: CA | AA17: 0000 | AC17: FUT Starlight T2 APD DRP | AD17: =SUM(AL:WY!AE17) -> 12500 | AE17: =SUM(AL:WY!AP17) -> 21996.52 | AF17: =SUM(AL:WY!BA17) -> 103850.88 | AG17: =SUM(AL:WY!BL17) -> 0 | AH17: =SUM(AL:WY!BW17) -> 0 | AI17: =SUM(AL:WY!CH17) -> 0 | AJ17: =SUM(AL:WY!CS17) -> 0 | AK17: =SUM(AL:WY!DD17) -> 0 | AL17: =SUM(AL:WY!DO17) -> 0 | AM17: =SUM(AL:WY!DZ17) -> 0 | AN17: =SUM(AL:WY!EK17) -> 0 | AO17: =SUM(AL:WY!EV17) -> 0 | AP17: =SUM(AD17:AO17) -> 138347.4
B18: Losses Incurred | C18: =SUM(C15:C17) -> 279524.74 | D18: =SUM(D15:D17) -> 100977.15 | E18: =SUM(E15:E17) -> 100000.76 | F18: =SUM(F15:F17) -> 98623.808 | G18: =SUM(G15:G17) -> 0 | H18: =SUM(H15:H17) -> 0 | I18: =SUM(I15:I17) -> 0 | J18: =SUM(J15:J17) -> 0 | ... Q18: =SUM(Q15:Q17) -> 579126.46 | T18: Payable to MGA | U18: 100 | V18: 264400 | W18: 00 | X18: 2002 | Y18: 000212 | Z18: 00 | AA18: 0000 | AC18: FUT Starlight T2 APD DRP | AD18: =SUM(AL:WY!AE18) -> -12500 | AE18: =SUM(AL:WY!AP18) -> -21996.52 | AF18: =SUM(AL:WY!BA18) -> -103850.88 | AG18: =SUM(AL:WY!BL18) -> 0 | AH18: =SUM(AL:WY!BW18) -> 0 | AI18: =SUM(AL:WY!CH18) -> 0 | AJ18: =SUM(AL:WY!CS18) -> 0 | AK18: =SUM(AL:WY!DD18) -> 0 | AL18: =SUM(AL:WY!DO18) -> 0 | AM18: =SUM(AL:WY!DZ18) -> 0 | AN18: =SUM(AL:WY!EK18) -> 0 | AO18: =SUM(AL:WY!EV18) -> 0 | AP18: =SUM(AD18:AO18) -> -138347.4
T19: Amounts recoverable from reinsurers | U19: 100 | V19: 125100 | W19: 00 | X19: 2002 | Y19: 000212 | Z19: 00 | AA19: 0000 | AC19: FUT Starlight T2 APD DRP | AD19: =SUM(AL:WY!AE19) -> 12500 | AE19: =SUM(AL:WY!AP19) -> 21996.52 | AF19: =SUM(AL:WY!BA19) -> 103850.88 | AG19: =SUM(AL:WY!BL19) -> 0 | AH19: =SUM(AL:WY!BW19) -> 0 | AI19: =SUM(AL:WY!CH19) -> 0 | AJ19: =SUM(AL:WY!CS19) -> 0 | AK19: =SUM(AL:WY!DD19) -> 0 | AL19: =SUM(AL:WY!DO19) -> 0 | AM19: =SUM(AL:WY!DZ19) -> 0 | AN19: =SUM(AL:WY!EK19) -> 0 | AO19: =SUM(AL:WY!EV19) -> 0 | AP19: =SUM(AD19:AO19) -> 138347.4
A20: d. | B20: Defense and Cost Containment Expense Paid (DCC) | C20: =SUM(AL:WY!C20) -> 0 | D20: =SUM(AL:WY!D20) -> 0 | E20: =SUM(AL:WY!E20) -> 0 | F20: =SUM(AL:WY!F20) -> 0 | G20: =SUM(AL:WY!G20) -> 0 | H20: =SUM(AL:WY!H20) -> 0 | I20: =SUM(AL:WY!I20) -> 0 | J20: =SUM(AL:WY!J20) -> 0 | ... O20: =SUM(AL:WY!O20) -> 0 | P20: =SUM(D20:O20) -> 0 | Q20: =+C20+P20 -> 0 | S20: =Q20-R20 -> 0 | T20: Ceded Losses Paid | U20: 100 | V20: 600300 | W20: 00 | X20: 2002 | Y20: 000212 | Z20: 00 | AA20: 0000 | AC20: FUT Starlight T2 APD DRP | AD20: =SUM(AL:WY!AE20) -> -12500 | AE20: =SUM(AL:WY!AP20) -> -21996.52 | AF20: =SUM(AL:WY!BA20) -> -103850.88 | AG20: =SUM(AL:WY!BL20) -> 0 | AH20: =SUM(AL:WY!BW20) -> 0 | AI20: =SUM(AL:WY!CH20) -> 0 | AJ20: =SUM(AL:WY!CS20) -> 0 | AK20: =SUM(AL:WY!DD20) -> 0 | AL20: =SUM(AL:WY!DO20) -> 0 | AM20: =SUM(AL:WY!DZ20) -> 0 | AN20: =SUM(AL:WY!EK20) -> 0 | AO20: =SUM(AL:WY!EV20) -> 0 | AP20: =SUM(AD20:AO20) -> -138347.4
B21: Change in DCC Reserves | C21: =SUM(AL:WY!C21) -> 0 | D21: =SUM(AL:WY!D21) -> 0 | E21: =SUM(AL:WY!E21) -> 0 | F21: =SUM(AL:WY!F21) -> 0 | G21: =SUM(AL:WY!G21) -> 0 | H21: =SUM(AL:WY!H21) -> 0 | I21: =SUM(AL:WY!I21) -> 0 | J21: =SUM(AL:WY!J21) -> 0 | ... O21: =SUM(AL:WY!O21) -> 0 | P21: =SUM(D21:O21) -> 0 | Q21: =+C21+P21 -> 0 | T21: Change in Case Loss Reserves - Direct | U21: 100 | V21: 550100 | W21: 00 | X21: 2002 | Y21: 000212 | Z21: CA | AA21: 0000 | AC21: FUT Starlight T2 APD DRP | AD21: =SUM(AL:WY!AE21) -> 60564 | AE21: =SUM(AL:WY!AP21) -> 13600.51 | AF21: =SUM(AL:WY!BA21) -> 152500 | AG21: =SUM(AL:WY!BL21) -> 0 | AH21: =SUM(AL:WY!BW21) -> 0 | AI21: =SUM(AL:WY!CH21) -> 0 | AJ21: =SUM(AL:WY!CS21) -> 0 | AK21: =SUM(AL:WY!DD21) -> 0 | AL21: =SUM(AL:WY!DO21) -> 0 | AM21: =SUM(AL:WY!DZ21) -> 0 | AN21: =SUM(AL:WY!EK21) -> 0 | AO21: =SUM(AL:WY!EV21) -> 0 | AP21: =SUM(AD21:AO21) -> 226664.51
B22: Change in DCC IBNR Reserves | C22: =SUM(AL:WY!C22) -> 0 | D22: =SUM(AL:WY!D22) -> 0 | E22: =SUM(AL:WY!E22) -> 0 | F22: =SUM(AL:WY!F22) -> 0 | G22: =SUM(AL:WY!G22) -> 0 | H22: =SUM(AL:WY!H22) -> 0 | I22: =SUM(AL:WY!I22) -> 0 | J22: =SUM(AL:WY!J22) -> 0 | ... O22: =SUM(AL:WY!O22) -> 0 | P22: =SUM(D22:O22) -> 0 | Q22: =+C22+P22 -> 0 | T22: Case Loss Reserves - Direct | U22: 100 | V22: 200100 | W22: 00 | X22: 2002 | Y22: 000212 | Z22: CA | AA22: 0000 | AC22: FUT Starlight T2 APD DRP | AD22: =SUM(AL:WY!AE22) -> -60564 | AE22: =SUM(AL:WY!AP22) -> -13600.51 | AF22: =SUM(AL:WY!BA22) -> -152500 | AG22: =SUM(AL:WY!BL22) -> 0 | AH22: =SUM(AL:WY!BW22) -> 0 | AI22: =SUM(AL:WY!CH22) -> 0 | AJ22: =SUM(AL:WY!CS22) -> 0 | AK22: =SUM(AL:WY!DD22) -> 0 | AL22: =SUM(AL:WY!DO22) -> 0 | AM22: =SUM(AL:WY!DZ22) -> 0 | AN22: =SUM(AL:WY!EK22) -> 0 | AO22: =SUM(AL:WY!EV22) -> 0 | AP22: =SUM(AD22:AO22) -> -226664.51
A23: e. | B23: Adjusting & Other Expense Paid (AOE) | C23: =SUM(AL:WY!C23) -> 867.5 | D23: =SUM(AL:WY!D23) -> 0 | E23: =SUM(AL:WY!E23) -> 2167.4 | F23: =SUM(AL:WY!F23) -> 2127.5 | G23: =SUM(AL:WY!G23) -> 0 | H23: =SUM(AL:WY!H23) -> 0 | I23: =SUM(AL:WY!I23) -> 0 | J23: =SUM(AL:WY!J23) -> 0 | ... O23: =SUM(AL:WY!O23) -> 0 | P23: =SUM(D23:O23) -> 4294.9 | Q23: =+C23+P23 -> 5162.4 | R23: =SUM(AL:WY!R23) -> 5162.4 | S23: =Q23-R23 -> 0 | T23: Case Loss Reserves - Ceded | U23: 100 | V23: 200300 | W23: 00 | X23: 2002 | Y23: 000212 | Z23: 00 | AA23: 0000 | AC23: FUT Starlight T2 APD DRP | AD23: =SUM(AL:WY!AE23) -> 60564 | AE23: =SUM(AL:WY!AP23) -> 13600.51 | AF23: =SUM(AL:WY!BA23) -> 152500 | AG23: =SUM(AL:WY!BL23) -> 0 | AH23: =SUM(AL:WY!BW23) -> 0 | AI23: =SUM(AL:WY!CH23) -> 0 | AJ23: =SUM(AL:WY!CS23) -> 0 | AK23: =SUM(AL:WY!DD23) -> 0 | AL23: =SUM(AL:WY!DO23) -> 0 | AM23: =SUM(AL:WY!DZ23) -> 0 | AN23: =SUM(AL:WY!EK23) -> 0 | AO23: =SUM(AL:WY!EV23) -> 0 | AP23: =SUM(AD23:AO23) -> 226664.51
B24: Change in AOE Reserves | C24: =SUM(AL:WY!C24) -> 12500 | D24: =SUM(AL:WY!D24) -> 5000 | E24: =SUM(AL:WY!E24) -> 3692.6 | F24: =SUM(AL:WY!F24) -> -5597.6 | G24: =SUM(AL:WY!G24) -> 0 | H24: =SUM(AL:WY!H24) -> 0 | I24: =SUM(AL:WY!I24) -> 0 | J24: =SUM(AL:WY!J24) -> 0 | ... O24: =SUM(AL:WY!O24) -> 0 | P24: =SUM(D24:O24) -> 3095 | Q24: =+C24+P24 -> 15595 | T24: Change in Case Loss Reserves - Ceded | U24: 100 | V24: 550300 | W24: 00 | X24: 2002 | Y24: 000212 | Z24: 00 | AA24: 0000 | AC24: FUT Starlight T2 APD DRP | AD24: =SUM(AL:WY!AE24) -> -60564 | AE24: =SUM(AL:WY!AP24) -> -13600.51 | AF24: =SUM(AL:WY!BA24) -> -152500 | AG24: =SUM(AL:WY!BL24) -> 0 | AH24: =SUM(AL:WY!BW24) -> 0 | AI24: =SUM(AL:WY!CH24) -> 0 | AJ24: =SUM(AL:WY!CS24) -> 0 | AK24: =SUM(AL:WY!DD24) -> 0 | AL24: =SUM(AL:WY!DO24) -> 0 | AM24: =SUM(AL:WY!DZ24) -> 0 | AN24: =SUM(AL:WY!EK24) -> 0 | AO24: =SUM(AL:WY!EV24) -> 0 | AP24: =SUM(AD24:AO24) -> -226664.51
B25: Change in AOE IBNR Reserves | C25: =SUM(AL:WY!C25) -> 52809.736 | D25: =SUM(AL:WY!D25) -> 18906.251 | E25: =SUM(AL:WY!E25) -> 17815.091 | F25: =SUM(AL:WY!F25) -> 26819.199 | G25: =SUM(AL:WY!G25) -> 0 | H25: =SUM(AL:WY!H25) -> 0 | I25: =SUM(AL:WY!I25) -> 0 | J25: =SUM(AL:WY!J25) -> 0 | ... O25: =SUM(AL:WY!O25) -> 0 | P25: =SUM(D25:O25) -> 63540.541 | Q25: =+C25+P25 -> 116350.28 | T25: Change in IBNR Loss Reserves - Direct | U25: 100 | V25: 550400 | W25: 00 | X25: 2002 | Y25: 000212 | Z25: CA | AA25: 0000 | AC25: FUT Starlight T2 APD DRP | AD25: =SUM(AL:WY!AE25) -> 27913.151 | AE25: =SUM(AL:WY!AP25) -> 64403.725 | AF25: =SUM(AL:WY!BA25) -> -157727.07 | AG25: =SUM(AL:WY!BL25) -> 0 | AH25: =SUM(AL:WY!BW25) -> 0 | AI25: =SUM(AL:WY!CH25) -> 0 | AJ25: =SUM(AL:WY!CS25) -> 0 | AK25: =SUM(AL:WY!DD25) -> 0 | AL25: =SUM(AL:WY!DO25) -> 0 | AM25: =SUM(AL:WY!DZ25) -> 0 | AN25: =SUM(AL:WY!EK25) -> 0 | AO25: =SUM(AL:WY!EV25) -> 0 | AP25: =SUM(AD25:AO25) -> -65410.196
A26: f. | B26: Unallocated Loss Adjustment Expense at 7% | C26: =SUM(AL:WY!C26) -> 149491.29 | D26: =SUM(AL:WY!D26) -> -280.2212 | E26: =SUM(AL:WY!E26) -> -2241.6429 | F26: =SUM(AL:WY!F26) -> -595.5152 | G26: =SUM(AL:WY!G26) -> 0 | H26: =SUM(AL:WY!H26) -> 0 | I26: =SUM(AL:WY!I26) -> 0 | J26: =SUM(AL:WY!J26) -> 0 | ... O26: =SUM(AL:WY!O26) -> 0 | P26: =SUM(D26:O26) -> -3117.3793 | Q26: =+C26+P26 -> 146373.91 | T26: IBNR Loss Reserves - Direct | U26: 100 | V26: 200400 | W26: 00 | X26: 2002 | Y26: 000212 | Z26: CA | AA26: 0000 | AC26: FUT Starlight T2 APD DRP | AD26: =SUM(AL:WY!AE26) -> -27913.151 | AE26: =SUM(AL:WY!AP26) -> -64403.725 | AF26: =SUM(AL:WY!BA26) -> 157727.07 | AG26: =SUM(AL:WY!BL26) -> 0 | AH26: =SUM(AL:WY!BW26) -> 0 | AI26: =SUM(AL:WY!CH26) -> 0 | AJ26: =SUM(AL:WY!CS26) -> 0 | AK26: =SUM(AL:WY!DD26) -> 0 | AL26: =SUM(AL:WY!DO26) -> 0 | AM26: =SUM(AL:WY!DZ26) -> 0 | AN26: =SUM(AL:WY!EK26) -> 0 | AO26: =SUM(AL:WY!EV26) -> 0 | AP26: =SUM(AD26:AO26) -> 65410.196
B27: Change in ULAE IBNR Reserves | C27: =SUM(AL:WY!C27) -> 1229.0722 | D27: =SUM(AL:WY!D27) -> 290.97575 | E27: =SUM(AL:WY!E27) -> 356.0199 | F27: =SUM(AL:WY!F27) -> -407.38536 | G27: =SUM(AL:WY!G27) -> 0 | H27: =SUM(AL:WY!H27) -> 0 | I27: =SUM(AL:WY!I27) -> 0 | J27: =SUM(AL:WY!J27) -> 0 | ... O27: =SUM(AL:WY!O27) -> 0 | P27: =SUM(D27:O27) -> 239.61029 | Q27: =+C27+P27 -> 1468.6825 | T27: IBNR Loss Reserves - Ceded | U27: 100 | V27: 200600 | W27: 00 | X27: 2002 | Y27: 000212 | Z27: 00 | AA27: 0000 | AC27: FUT Starlight T2 APD DRP | AD27: =SUM(AL:WY!AE27) -> 27913.151 | AE27: =SUM(AL:WY!AP27) -> 64403.725 | AF27: =SUM(AL:WY!BA27) -> -157727.07 | AG27: =SUM(AL:WY!BL27) -> 0 | AH27: =SUM(AL:WY!BW27) -> 0 | AI27: =SUM(AL:WY!CH27) -> 0 | AJ27: =SUM(AL:WY!CS27) -> 0 | AK27: =SUM(AL:WY!DD27) -> 0 | AL27: =SUM(AL:WY!DO27) -> 0 | AM27: =SUM(AL:WY!DZ27) -> 0 | AN27: =SUM(AL:WY!EK27) -> 0 | AO27: =SUM(AL:WY!EV27) -> 0 | AP27: =SUM(AD27:AO27) -> -65410.196
B28: Loss Adjustment Expenses Incurred | C28: =SUM(C20:C27) -> 216897.6 | D28: =SUM(D20:D27) -> 23917.006 | E28: =SUM(E20:E27) -> 21789.468 | F28: =SUM(F20:F27) -> 22346.199 | G28: =SUM(G20:G27) -> 0 | H28: =SUM(H20:H27) -> 0 | I28: =SUM(I20:I27) -> 0 | J28: =SUM(J20:J27) -> 0 | ... Q28: =SUM(Q20:Q27) -> 284950.27 | T28: Change in IBNR Loss Reserves - Ceded | U28: 100 | V28: 550600 | W28: 00 | X28: 2002 | Y28: 000212 | Z28: 00 | AA28: 0000 | AC28: FUT Starlight T2 APD DRP | AD28: =SUM(AL:WY!AE28) -> -27913.151 | AE28: =SUM(AL:WY!AP28) -> -64403.725 | AF28: =SUM(AL:WY!BA28) -> 157727.07 | AG28: =SUM(AL:WY!BL28) -> 0 | AH28: =SUM(AL:WY!BW28) -> 0 | AI28: =SUM(AL:WY!CH28) -> 0 | AJ28: =SUM(AL:WY!CS28) -> 0 | AK28: =SUM(AL:WY!DD28) -> 0 | AL28: =SUM(AL:WY!DO28) -> 0 | AM28: =SUM(AL:WY!DZ28) -> 0 | AN28: =SUM(AL:WY!EK28) -> 0 | AO28: =SUM(AL:WY!EV28) -> 0 | AP28: =SUM(AD28:AO28) -> 65410.196
D29: =+D15+D23+D26 -> 12219.779 | E29: =+E15+E23+E26 -> 21922.277 | F29: =+F15+F23+F26 -> 105382.86 | G29: =+G15+G23+G26 -> 0 | H29: =+H15+H23+H26 -> 0 | I29: =+I15+I23+I26 -> 0 | J29: =+J15+J23+J26 -> 0 | K29: =+K15+K23+K26 -> 0 | ... O29: =+O15+O23+O26 -> 0 | T29: Direct LAE DCC Paid | U29: 100 | V29: 601100 | W29: 00 | X29: 2002 | Y29: 000212 | Z29: CA | AA29: 0000 | AC29: FUT Starlight T2 APD DRP | AD29: =SUM(AL:WY!AE29) -> 0 | AE29: =SUM(AL:WY!AP29) -> 0 | AF29: =SUM(AL:WY!BA29) -> 0 | AG29: =SUM(AL:WY!BL29) -> 0 | AH29: =SUM(AL:WY!BW29) -> 0 | AI29: =SUM(AL:WY!CH29) -> 0 | AJ29: =SUM(AL:WY!CS29) -> 0 | AK29: =SUM(AL:WY!DD29) -> 0 | AL29: =SUM(AL:WY!DO29) -> 0 | AM29: =SUM(AL:WY!DZ29) -> 0 | AN29: =SUM(AL:WY!EK29) -> 0 | AO29: =SUM(AL:WY!EV29) -> 0 | AP29: =SUM(AD29:AO29) -> 0
A30: g. | B30: Boards & Bureaus / ISO Charge at .4% | C30: =SUM(AL:WY!C30) -> 8542.3595 | D30: =SUM(AL:WY!D30) -> -16.01264 | E30: =SUM(AL:WY!E30) -> -128.09388 | F30: =SUM(AL:WY!F30) -> -34.02944 | G30: =SUM(AL:WY!G30) -> 0 | H30: =SUM(AL:WY!H30) -> 0 | I30: =SUM(AL:WY!I30) -> 0 | J30: =SUM(AL:WY!J30) -> 0 | ... O30: =SUM(AL:WY!O30) -> 0 | P30: =SUM(D30:O30) -> -178.13596 | Q30: =+C30+P30 -> 8364.2235 | T30: Payable to MGA | U30: 100 | V30: 264400 | W30: 00 | X30: 2002 | Y30: 000212 | Z30: 00 | AA30: 0000 | AC30: FUT Starlight T2 APD DRP | AD30: =SUM(AL:WY!AE30) -> 0 | AE30: =SUM(AL:WY!AP30) -> 0 | AF30: =SUM(AL:WY!BA30) -> 0 | AG30: =SUM(AL:WY!BL30) -> 0 | AH30: =SUM(AL:WY!BW30) -> 0 | AI30: =SUM(AL:WY!CH30) -> 0 | AJ30: =SUM(AL:WY!CS30) -> 0 | AK30: =SUM(AL:WY!DD30) -> 0 | AL30: =SUM(AL:WY!DO30) -> 0 | AM30: =SUM(AL:WY!DZ30) -> 0 | AN30: =SUM(AL:WY!EK30) -> 0 | AO30: =SUM(AL:WY!EV30) -> 0 | AP30: =SUM(AD30:AO30) -> 0
B31: Boards & Bureaus / ISO Charge at .4% on UEP | C31: =SUM(AL:WY!C31) -> -6566.9196 | D31: =SUM(AL:WY!D31) -> 729.63208 | E31: =SUM(AL:WY!E31) -> 834.813 | F31: =SUM(AL:WY!F31) -> 731.01748 | G31: =SUM(AL:WY!G31) -> 0 | H31: =SUM(AL:WY!H31) -> 0 | I31: =SUM(AL:WY!I31) -> 0 | J31: =SUM(AL:WY!J31) -> 0 | ... O31: =SUM(AL:WY!O31) -> 0 | P31: =SUM(D31:O31) -> 2295.4626 | Q31: =+C31+P31 -> -4271.457 | T31: Amounts recoverable from reinsurers | U31: 100 | V31: 125100 | W31: 00 | X31: 2002 | Y31: 000212 | Z31: 00 | AA31: 0000 | AC31: FUT Starlight T2 APD DRP | AD31: =SUM(AL:WY!AE31) -> 0 | AE31: =SUM(AL:WY!AP31) -> 0 | AF31: =SUM(AL:WY!BA31) -> 0 | AG31: =SUM(AL:WY!BL31) -> 0 | AH31: =SUM(AL:WY!BW31) -> 0 | AI31: =SUM(AL:WY!CH31) -> 0 | AJ31: =SUM(AL:WY!CS31) -> 0 | AK31: =SUM(AL:WY!DD31) -> 0 | AL31: =SUM(AL:WY!DO31) -> 0 | AM31: =SUM(AL:WY!DZ31) -> 0 | AN31: =SUM(AL:WY!EK31) -> 0 | AO31: =SUM(AL:WY!EV31) -> 0 | AP31: =SUM(AD31:AO31) -> 0
A32: h. | B32: Loss Ratio Cap Charge at 0% | C32: =SUM(AL:WY!C32) -> 42711.797 | D32: =SUM(AL:WY!D32) -> -80.0632 | E32: =SUM(AL:WY!E32) -> -640.4694 | F32: =SUM(AL:WY!F32) -> -170.1472 | G32: =SUM(AL:WY!G32) -> 0 | H32: =SUM(AL:WY!H32) -> 0 | I32: =SUM(AL:WY!I32) -> 0 | J32: =SUM(AL:WY!J32) -> 0 | ... O32: =SUM(AL:WY!O32) -> 0 | P32: =SUM(D32:O32) -> -890.6798 | Q32: =+C32+P32 -> 41821.118 | T32: Ceded LAE DCC Paid | U32: 100 | V32: 601300 | W32: 00 | X32: 2002 | Y32: 000212 | Z32: 00 | AA32: 0000 | AC32: FUT Starlight T2 APD DRP | AD32: =SUM(AL:WY!AE32) -> 0 | AE32: =SUM(AL:WY!AP32) -> 0 | AF32: =SUM(AL:WY!BA32) -> 0 | AG32: =SUM(AL:WY!BL32) -> 0 | AH32: =SUM(AL:WY!BW32) -> 0 | AI32: =SUM(AL:WY!CH32) -> 0 | AJ32: =SUM(AL:WY!CS32) -> 0 | AK32: =SUM(AL:WY!DD32) -> 0 | AL32: =SUM(AL:WY!DO32) -> 0 | AM32: =SUM(AL:WY!DZ32) -> 0 | AN32: =SUM(AL:WY!EK32) -> 0 | AO32: =SUM(AL:WY!EV32) -> 0 | AP32: =SUM(AD32:AO32) -> 0
B33: Loss Ratio Cap on UEP | C33: =SUM(AL:WY!C33) -> -32834.598 | D33: =SUM(AL:WY!D33) -> 3648.1604 | E33: =SUM(AL:WY!E33) -> 4174.065 | F33: =SUM(AL:WY!F33) -> 3655.0874 | G33: =SUM(AL:WY!G33) -> 0 | H33: =SUM(AL:WY!H33) -> 0 | I33: =SUM(AL:WY!I33) -> 0 | J33: =SUM(AL:WY!J33) -> 0 | ... O33: =SUM(AL:WY!O33) -> 0 | P33: =SUM(D33:O33) -> 11477.313 | Q33: =+C33+P33 -> -21357.285 | T33: Change in LAE DCC Reserves - Direct | U33: 100 | V33: 557100 | W33: 00 | X33: 2002 | Y33: 000212 | Z33: CA | AA33: 0000 | AC33: FUT Starlight T2 APD DRP | AD33: =SUM(AL:WY!AE33) -> 0 | AE33: =SUM(AL:WY!AP33) -> 0 | AF33: =SUM(AL:WY!BA33) -> 0 | AG33: =SUM(AL:WY!BL33) -> 0 | AH33: =SUM(AL:WY!BW33) -> 0 | AI33: =SUM(AL:WY!CH33) -> 0 | AJ33: =SUM(AL:WY!CS33) -> 0 | AK33: =SUM(AL:WY!DD33) -> 0 | AL33: =SUM(AL:WY!DO33) -> 0 | AM33: =SUM(AL:WY!DZ33) -> 0 | AN33: =SUM(AL:WY!EK33) -> 0 | AO33: =SUM(AL:WY!EV33) -> 0 | AP33: =SUM(AD33:AO33) -> 0
B34: Other Expenses Incurred | C34: =SUM(C30:C33) -> 11852.639 | D34: =SUM(D30:D33) -> 4281.7166 | E34: =SUM(E30:E33) -> 4240.3147 | F34: =SUM(F30:F33) -> 4181.9282 | G34: =SUM(G30:G33) -> 0 | H34: =SUM(H30:H33) -> 0 | I34: =SUM(I30:I33) -> 0 | J34: =SUM(J30:J33) -> 0 | ... Q34: =SUM(Q30:Q33) -> 24556.599 | T34: LAE DCC Reserves - Direct | U34: 100 | V34: 207100 | W34: 00 | X34: 2002 | Y34: 000212 | Z34: CA | AA34: 0000 | AC34: FUT Starlight T2 APD DRP | AD34: =SUM(AL:WY!AE34) -> 0 | AE34: =SUM(AL:WY!AP34) -> 0 | AF34: =SUM(AL:WY!BA34) -> 0 | AG34: =SUM(AL:WY!BL34) -> 0 | AH34: =SUM(AL:WY!BW34) -> 0 | AI34: =SUM(AL:WY!CH34) -> 0 | AJ34: =SUM(AL:WY!CS34) -> 0 | AK34: =SUM(AL:WY!DD34) -> 0 | AL34: =SUM(AL:WY!DO34) -> 0 | AM34: =SUM(AL:WY!DZ34) -> 0 | AN34: =SUM(AL:WY!EK34) -> 0 | AO34: =SUM(AL:WY!EV34) -> 0 | AP34: =SUM(AD34:AO34) -> 0
T35: LAE DCC Reserves - Ceded | U35: 100 | V35: 207300 | W35: 00 | X35: 2002 | Y35: 000212 | Z35: 00 | AA35: 0000 | AC35: FUT Starlight T2 APD DRP | AD35: =SUM(AL:WY!AE35) -> 0 | AE35: =SUM(AL:WY!AP35) -> 0 | AF35: =SUM(AL:WY!BA35) -> 0 | AG35: =SUM(AL:WY!BL35) -> 0 | AH35: =SUM(AL:WY!BW35) -> 0 | AI35: =SUM(AL:WY!CH35) -> 0 | AJ35: =SUM(AL:WY!CS35) -> 0 | AK35: =SUM(AL:WY!DD35) -> 0 | AL35: =SUM(AL:WY!DO35) -> 0 | AM35: =SUM(AL:WY!DZ35) -> 0 | AN35: =SUM(AL:WY!EK35) -> 0 | AO35: =SUM(AL:WY!EV35) -> 0 | AP35: =SUM(AD35:AO35) -> 0
T36: Change in LAE DCC Reserves - Ceded | U36: 100 | V36: 557300 | W36: 00 | X36: 2002 | Y36: 000212 | Z36: 00 | AA36: 0000 | AC36: FUT Starlight T2 APD DRP | AD36: =SUM(AL:WY!AE36) -> 0 | AE36: =SUM(AL:WY!AP36) -> 0 | AF36: =SUM(AL:WY!BA36) -> 0 | AG36: =SUM(AL:WY!BL36) -> 0 | AH36: =SUM(AL:WY!BW36) -> 0 | AI36: =SUM(AL:WY!CH36) -> 0 | AJ36: =SUM(AL:WY!CS36) -> 0 | AK36: =SUM(AL:WY!DD36) -> 0 | AL36: =SUM(AL:WY!DO36) -> 0 | AM36: =SUM(AL:WY!DZ36) -> 0 | AN36: =SUM(AL:WY!EK36) -> 0 | AO36: =SUM(AL:WY!EV36) -> 0 | AP36: =SUM(AD36:AO36) -> 0
B37: Total Profit (Loss) | C37: =+C8-C13-C18-C28-C34 -> -633736.07 | D37: =+D8-D13-D18-D28-D34 -> 50389.903 | E37: =+E8-E13-E18-E28-E34 -> 59936.049 | F37: =+F8-F13-F18-F28-F34 -> 51562.21 | G37: =+G8-G13-G18-G28-G34 -> 0 | H37: =+H8-H13-H18-H28-H34 -> 0 | I37: =+I8-I13-I18-I28-I34 -> 0 | J37: =+J8-J13-J18-J28-J34 -> 0 | ... Q37: =+Q8-Q13-Q18-Q28-Q34 -> -471847.91 | T37: Change in IBNR DCC Reserves - Direct | U37: 100 | V37: 557400 | W37: 00 | X37: 2002 | Y37: 000212 | Z37: CA | AA37: 0000 | AC37: FUT Starlight T2 APD DRP | AD37: =SUM(AL:WY!AE37) -> 0 | AE37: =SUM(AL:WY!AP37) -> 0 | AF37: =SUM(AL:WY!BA37) -> 0 | AG37: =SUM(AL:WY!BL37) -> 0 | AH37: =SUM(AL:WY!BW37) -> 0 | AI37: =SUM(AL:WY!CH37) -> 0 | AJ37: =SUM(AL:WY!CS37) -> 0 | AK37: =SUM(AL:WY!DD37) -> 0 | AL37: =SUM(AL:WY!DO37) -> 0 | AM37: =SUM(AL:WY!DZ37) -> 0 | AN37: =SUM(AL:WY!EK37) -> 0 | AO37: =SUM(AL:WY!EV37) -> 0 | AP37: =SUM(AD37:AO37) -> 0
P38: =+P37-AL!P37-AR!P37-AZ!P37-CA!P37-CO!P37-CT!P37-DE!P37-FL!P37-GA!P37-HI!P37-ID!P37-IL!P37-IN!P37-KS!P37-LA!P37-MD!P37-MI!P37-MN!P37-MO!P37-MS!P37-NC!P37-NJ!P37-NE!P37-NV!P37-NY!P37-OH!P37-OK!P37-OR!P37-PA!P37-SC!P37-SD!P37-TN!P37-TX!P37-VA!P37-WA!P37-WI!P37-WY!P37 -> -842.70435 | Q38: =+Q37-AL!Q37-AR!Q37-AZ!Q37-CA!Q37-CO!Q37-CT!Q37-DE!Q37-FL!Q37-GA!Q37-HI!Q37-ID!Q37-IL!Q37-IN!Q37-KS!Q37-LA!Q37-MD!Q37-MI!Q37-MN!Q37-MO!Q37-MS!Q37-NC!Q37-NJ!Q37-NE!Q37-NV!Q37-NY!Q37-OH!Q37-OK!Q37-OR!Q37-PA!Q37-SC!Q37-SD!Q37-TN!Q37-TX!Q37-VA!Q37-WA!Q37-WI!Q37-WY!Q37 -> -1439.0681 | T38: IBNR DCC Reserves - Direct | U38: 100 | V38: 207400 | W38: 00 | X38: 2002 | Y38: 000212 | Z38: CA | AA38: 0000 | AC38: FUT Starlight T2 APD DRP | AD38: =SUM(AL:WY!AE38) -> 0 | AE38: =SUM(AL:WY!AP38) -> 0 | AF38: =SUM(AL:WY!BA38) -> 0 | AG38: =SUM(AL:WY!BL38) -> 0 | AH38: =SUM(AL:WY!BW38) -> 0 | AI38: =SUM(AL:WY!CH38) -> 0 | AJ38: =SUM(AL:WY!CS38) -> 0 | AK38: =SUM(AL:WY!DD38) -> 0 | AL38: =SUM(AL:WY!DO38) -> 0 | AM38: =SUM(AL:WY!DZ38) -> 0 | AN38: =SUM(AL:WY!EK38) -> 0 | AO38: =SUM(AL:WY!EV38) -> 0 | AP38: =SUM(AD38:AO38) -> 0
A39: i. | B39: Reinsurance Brokerage Fee | C39: =SUM(AL:WY!C39) -> 0 | D39: =SUM(AL:WY!D39) -> 0 | E39: =SUM(AL:WY!E39) -> 0 | F39: =SUM(AL:WY!F39) -> 0 | G39: =SUM(AL:WY!G39) -> 0 | H39: =SUM(AL:WY!H39) -> 0 | I39: =SUM(AL:WY!I39) -> 0 | J39: =SUM(AL:WY!J39) -> 0 | ... O39: =SUM(AL:WY!O39) -> 0 | P39: =SUM(D39:O39) -> 0 | Q39: =+C39+P39 -> 0 | T39: IBNR DCC Reserves - Ceded | U39: 100 | V39: 207600 | W39: 00 | X39: 2002 | Y39: 000212 | Z39: 00 | AA39: 0000 | AC39: FUT Starlight T2 APD DRP | AD39: =SUM(AL:WY!AE39) -> 0 | AE39: =SUM(AL:WY!AP39) -> 0 | AF39: =SUM(AL:WY!BA39) -> 0 | AG39: =SUM(AL:WY!BL39) -> 0 | AH39: =SUM(AL:WY!BW39) -> 0 | AI39: =SUM(AL:WY!CH39) -> 0 | AJ39: =SUM(AL:WY!CS39) -> 0 | AK39: =SUM(AL:WY!DD39) -> 0 | AL39: =SUM(AL:WY!DO39) -> 0 | AM39: =SUM(AL:WY!DZ39) -> 0 | AN39: =SUM(AL:WY!EK39) -> 0 | AO39: =SUM(AL:WY!EV39) -> 0 | AP39: =SUM(AD39:AO39) -> 0
T40: Change in IBNR DCC Reserves - Ceded | U40: 100 | V40: 557600 | W40: 00 | X40: 2002 | Y40: 000212 | Z40: 00 | AA40: 0000 | AC40: FUT Starlight T2 APD DRP | AD40: =SUM(AL:WY!AE40) -> 0 | AE40: =SUM(AL:WY!AP40) -> 0 | AF40: =SUM(AL:WY!BA40) -> 0 | AG40: =SUM(AL:WY!BL40) -> 0 | AH40: =SUM(AL:WY!BW40) -> 0 | AI40: =SUM(AL:WY!CH40) -> 0 | AJ40: =SUM(AL:WY!CS40) -> 0 | AK40: =SUM(AL:WY!DD40) -> 0 | AL40: =SUM(AL:WY!DO40) -> 0 | AM40: =SUM(AL:WY!DZ40) -> 0 | AN40: =SUM(AL:WY!EK40) -> 0 | AO40: =SUM(AL:WY!EV40) -> 0 | AP40: =SUM(AD40:AO40) -> 0
...

Sheet AL
A1: Southlake Specialty Insurance Company
C2: 2025 | P2: 2026
C3: ITD | P3: YTD | Q3: ITD | R3: System
B4: Starlight APD - AL | C4: Totals | D4: Jan-26 | E4: Feb-26 | F4: Mar-26 | G4: Apr-26 | H4: May-26 | I4: Jun-26 | J4: Jul-26 | K4: Aug-26 | L4: Sep-26 | M4: Oct-26 | N4: Nov-26 | O4: Dec-26 | P4: Totals | Q4: Totals | R4: Reports | S4: Variance | U4: Jan-26 Journal Entries | V4: Comp | W4: Account | X4: CC | Y4: MGA | Z4: LOB | AA4: ST | AB4: EXT | AC4: Sub | AD4: Description | AE4: DR / (CR) | AF4: Feb-26 Journal Entries | AG4: Comp | AH4: Account | AI4: CC | AJ4: MGA | AK4: LOB | AL4: ST | AM4: EXT | AN4: Sub | AO4: Description | AP4: DR / (CR) | AQ4: Mar-26 Journal Entries | AR4: Comp | AS4: Account | AT4: CC | AU4: MGA | AV4: LOB | AW4: ST | AX4: EXT | AY4: Sub | AZ4: Description | BA4: DR / (CR) | BB4: Apr-26 Journal Entries | BC4: Comp | BD4: Account | BE4: CC | BF4: MGA | BG4: LOB | BH4: ST | BI4: EXT | BJ4: Sub | BK4: Description | BL4: DR / (CR) | BM4: May-26 Journal Entries | BN4: Comp | BO4: Account | BP4: CC | BQ4: MGA | BR4: LOB | BS4: ST | BT4: EXT | BU4: Sub | BV4: Description | BW4: DR / (CR) | BX4: Jun-26 Journal Entries | BY4: Comp | BZ4: Account | CA4: CC | CB4: MGA | CC4: LOB | CD4: ST | CE4: EXT | CF4: Sub | CG4: Description | CH4: DR / (CR) | CI4: Jul-26 Journal Entries | CJ4: Comp | CK4: Account | CL4: CC | CM4: MGA | CN4: LOB | CO4: ST | CP4: EXT | CQ4: Sub | CR4: Description | CS4: DR / (CR) | CT4: Aug-26 Journal Entries | CU4: Comp | CV4: Account | CW4: CC | CX4: MGA | CY4: LOB | CZ4: ST | DA4: EXT | DB4: Sub | DC4: Description | DD4: DR / (CR) | DE4: Sep-26 Journal Entries | DF4: Comp | DG4: Account | DH4: CC | DI4: MGA | DJ4: LOB | DK4: ST | DL4: EXT | DM4: Sub | DN4: Description | DO4: DR / (CR) | DP4: Oct-26 Journal Entries | DQ4: Comp | DR4: Account | DS4: CC | DT4: MGA | DU4: LOB | DV4: ST | DW4: EXT | DX4: Sub | DY4: Description | DZ4: DR / (CR) | EA4: Nov-26 Journal Entries | EB4: Comp | EC4: Account | ED4: CC | EE4: MGA | EF4: LOB | EG4: ST | EH4: EXT | EI4: Sub | EJ4: Description | EK4: DR / (CR) | EL4: Dec-26 Journal Entries | EM4: Comp | EN4: Account | EO4: CC | EP4: MGA | EQ4: LOB | ER4: ST | ES4: EXT | ET4: Sub | EU4: Description | EV4: DR / (CR)
U5: Uncollected Premium Direct | V5: 100 | W5: 120100 | X5: 00 | Y5: 2002 | Z5: 000212 | AA5: 00 | AB5: 0000 | AD5: FUT Starlight T2 APD DRP | AE5: =+D6 -> 0 | AF5: Uncollected Premium Direct | AG5: 100 | AH5: 120100 | AI5: 00 | AJ5: 2002 | AK5: 000212 | AL5: 00 | AM5: 0000 | AO5: FUT Starlight T2 APD DRP | AP5: =+E6 -> 0 | AQ5: Uncollected Premium Direct | AR5: 100 | AS5: 120100 | AT5: 00 | AU5: 2002 | AV5: 000212 | AW5: 00 | AX5: 0000 | AZ5: FUT Starlight T2 APD DRP | BA5: =+F6 -> 0 | BB5: Uncollected Premium Direct | BC5: 100 | BD5: 120100 | BE5: 00 | BF5: 2002 | BG5: 000212 | BH5: 00 | BI5: 0000 | BK5: FUT Starlight T2 APD DRP | BL5: =+G6 -> 0 | BM5: Uncollected Premium Direct | BN5: 100 | BO5: 120100 | BP5: 00 | BQ5: 2002 | BR5: 000212 | BS5: 00 | BT5: 0000 | BV5: FUT Starlight T2 APD DRP | BW5: =+H6 -> 0 | BX5: Uncollected Premium Direct | BY5: 100 | BZ5: 120100 | CA5: 00 | CB5: 2002 | CC5: 000212 | CD5: 00 | CE5: 0000 | CG5: FUT Starlight T2 APD DRP | CH5: =+I6 -> 0 | CI5: Uncollected Premium Direct | CJ5: 100 | CK5: 120100 | CL5: 00 | CM5: 2002 | CN5: 000212 | CO5: 00 | CP5: 0000 | CR5: FUT Starlight T2 APD DRP | CS5: =+J6 -> 0 | CT5: Uncollected Premium Direct | CU5: 100 | CV5: 120100 | CW5: 00 | CX5: 2002 | CY5: 000212 | CZ5: 00 | DA5: 0000 | DC5: FUT Starlight T2 APD DRP | DD5: =+K6 -> 0 | DE5: Uncollected Premium Direct | DF5: 100 | DG5: 120100 | DH5: 00 | DI5: 2002 | DJ5: 000212 | DK5: 00 | DL5: 0000 | DN5: FUT Starlight T2 APD DRP | DO5: =+L6 -> 0 | DP5: Uncollected Premium Direct | DQ5: 100 | DR5: 120100 | DS5: 00 | DT5: 2002 | DU5: 000212 | DV5: 00 | DW5: 0000 | DY5: FUT Starlight T2 APD DRP | DZ5: =+M6 -> 0 | EA5: Uncollected Premium Direct | EB5: 100 | EC5: 120100 | ED5: 00 | EE5: 2002 | EF5: 000212 | EG5: 00 | EH5: 0000 | EJ5: FUT Starlight T2 APD DRP | EK5: =+N6 -> 0 | EL5: Uncollected Premium Direct | EM5: 100 | EN5: 120100 | EO5: 00 | EP5: 2002 | EQ5: 000212 | ER5: 00 | ES5: 0000 | EU5: FUT Starlight T2 APD DRP | EV5: =+O6 -> 0
A6: a. | B6: Premiums Written | C6: 0 | D6: 0 | P6: =SUM(D6:O6) -> 0 | Q6: =+C6+P6 -> 0 | R6: =Q6 -> 0 | S6: =Q6-R6 -> 0 | U6: Direct Premium Written | V6: 100 | W6: 400100 | X6: 00 | Y6: 2002 | Z6: 000212 | AA6: {=RIGHT(CELL("filename",A1),LEN(CELL("filename",A1))-FIND("]",CELL("filename",A1)))} -> #VALUE! | AB6: 0000 | AD6: FUT Starlight T2 APD DRP | AE6: =-D6 -> 0 | AF6: Direct Premium Written | AG6: 100 | AH6: 400100 | AI6: 00 | AJ6: 2002 | AK6: 000212 | AL6: {=RIGHT(CELL("filename",A1),LEN(CELL("filename",A1))-FIND("]",CELL("filename",A1)))} -> #VALUE! | AM6: 0000 | AO6: FUT Starlight T2 APD DRP | AP6: =-E6 -> 0 | AQ6: Direct Premium Written | AR6: 100 | AS6: 400100 | AT6: 00 | AU6: 2002 | AV6: 000212 | AW6: {=RIGHT(CELL("filename",A1),LEN(CELL("filename",A1))-FIND("]",CELL("filename",A1)))} -> #VALUE! | AX6: 0000 | AZ6: FUT Starlight T2 APD DRP | BA6: =-F6 -> 0 | BB6: Direct Premium Written | BC6: 100 | BD6: 400100 | BE6: 00 | BF6: 2002 | BG6: 000212 | BH6: {=RIGHT(CELL("filename",A1),LEN(CELL("filename",A1))-FIND("]",CELL("filename",A1)))} -> #VALUE! | BI6: 0000 | BK6: FUT Starlight T2 APD DRP | BL6: =-G6 -> 0 | BM6: Direct Premium Written | BN6: 100 | BO6: 400100 | BP6: 00 | BQ6: 2002 | BR6: 000212 | BS6: {=RIGHT(CELL("filename",A1),LEN(CELL("filename",A1))-FIND("]",CELL("filename",A1)))} -> #VALUE! | BT6: 0000 | BV6: FUT Starlight T2 APD DRP | BW6: =-H6 -> 0 | BX6: Direct Premium Written | BY6: 100 | BZ6: 400100 | CA6: 00 | CB6: 2002 | CC6: 000212 | CD6: {=RIGHT(CELL("filename",A1),LEN(CELL("filename",A1))-FIND("]",CELL("filename",A1)))} -> #VALUE! | CE6: 0000 | CG6: FUT Starlight T2 APD DRP | CH6: =-I6 -> 0 | CI6: Direct Premium Written | CJ6: 100 | CK6: 400100 | CL6: 00 | CM6: 2002 | CN6: 000212 | CO6: {=RIGHT(CELL("filename",A1),LEN(CELL("filename",A1))-FIND("]",CELL("filename",A1)))} -> #VALUE! | CP6: 0000 | CR6: FUT Starlight T2 APD DRP | CS6: =-J6 -> 0 | CT6: Direct Premium Written | CU6: 100 | CV6: 400100 | CW6: 00 | CX6: 2002 | CY6: 000212 | CZ6: {=RIGHT(CELL("filename",A1),LEN(CELL("filename",A1))-FIND("]",CELL("filename",A1)))} -> #VALUE! | DA6: 0000 | DC6: FUT Starlight T2 APD DRP | DD6: =-K6 -> 0 | DE6: Direct Premium Written | DF6: 100 | DG6: 400100 | DH6: 00 | DI6: 2002 | DJ6: 000212 | DK6: {=RIGHT(CELL("filename",A1),LEN(CELL("filename",A1))-FIND("]",CELL("filename",A1)))} -> #VALUE! | DL6: 0000 | DN6: FUT Starlight T2 APD DRP | DO6: =-L6 -> 0 | DP6: Direct Premium Written | DQ6: 100 | DR6: 400100 | DS6: 00 | DT6: 2002 | DU6: 000212 | DV6: {=RIGHT(CELL("filename",A1),LEN(CELL("filename",A1))-FIND("]",CELL("filename",A1)))} -> #VALUE! | DW6: 0000 | DY6: FUT Starlight T2 APD DRP | DZ6: =-M6 -> 0 | EA6: Direct Premium Written | EB6: 100 | EC6: 400100 | ED6: 00 | EE6: 2002 | EF6: 000212 | EG6: {=RIGHT(CELL("filename",A1),LEN(CELL("filename",A1))-FIND("]",CELL("filename",A1)))} -> #VALUE! | EH6: 0000 | EJ6: FUT Starlight T2 APD DRP | EK6: =-N6 -> 0 | EL6: Direct Premium Written | EM6: 100 | EN6: 400100 | EO6: 00 | EP6: 2002 | EQ6: 000212 | ER6: {=RIGHT(CELL("filename",A1),LEN(CELL("filename",A1))-FIND("]",CELL("filename",A1)))} -> #VALUE! | ES6: 0000 | EU6: FUT Starlight T2 APD DRP | EV6: =-O6 -> 0
B7: Change in UEP | C7: 0 | D7: =C51-D51 -> 0 | P7: =SUM(D7:O7) -> 0 | Q7: =+C7+P7 -> 0 | R7: =Q7 -> 0 | S7: =Q7-R7 -> 0 | U7: Change in Unearned Premium Direct | V7: 100 | W7: 411100 | X7: 00 | Y7: 2002 | Z7: 000212 | AA7: {=RIGHT(CELL("filename",A1),LEN(CELL("filename",A1))-FIND("]",CELL("filename",A1)))} -> #VALUE! | AB7: 0000 | AD7: FUT Starlight T2 APD DRP | AE7: =-D7 -> 0 | AF7: Change in Unearned Premium Direct | AG7: 100 | AH7: 411100 | AI7: 00 | AJ7: 2002 | AK7: 000212 | AL7: {=RIGHT(CELL("filename",A1),LEN(CELL("filename",A1))-FIND("]",CELL("filename",A1)))} -> #VALUE! | AM7: 0000 | AO7: FUT Starlight T2 APD DRP | AP7: =-E7 -> 0 | AQ7: Change in Unearned Premium Direct | AR7: 100 | AS7: 411100 | AT7: 00 | AU7: 2002 | AV7: 000212 | AW7: {=RIGHT(CELL("filename",A1),LEN(CELL("filename",A1))-FIND("]",CELL("filename",A1)))} -> #VALUE! | AX7: 0000 | AZ7: FUT Starlight T2 APD DRP | BA7: =-F7 -> 0 | BB7: Change in Unearned Premium Direct | BC7: 100 | BD7: 411100 | BE7: 00 | BF7: 2002 | BG7: 000212 | BH7: {=RIGHT(CELL("filename",A1),LEN(CELL("filename",A1))-FIND("]",CELL("filename",A1)))} -> #VALUE! | BI7: 0000 | BK7: FUT Starlight T2 APD DRP | BL7: =-G7 -> 0 | BM7: Change in Unearned Premium Direct | BN7: 100 | BO7: 411100 | BP7: 00 | BQ7: 2002 | BR7: 000212 | BS7: {=RIGHT(CELL("filename",A1),LEN(CELL("filename",A1))-FIND("]",CELL("filename",A1)))} -> #VALUE! | BT7: 0000 | BV7: FUT Starlight T2 APD DRP | BW7: =-H7 -> 0 | BX7: Change in Unearned Premium Direct | BY7: 100 | BZ7: 411100 | CA7: 00 | CB7: 2002 | CC7: 000212 | CD7: {=RIGHT(CELL("filename",A1),LEN(CELL("filename",A1))-FIND("]",CELL("filename",A1)))} -> #VALUE! | CE7: 0000 | CG7: FUT Starlight T2 APD DRP | CH7: =-I7 -> 0 | CI7: Change in Unearned Premium Direct | CJ7: 100 | CK7: 411100 | CL7: 00 | CM7: 2002 | CN7: 000212 | CO7: {=RIGHT(CELL("filename",A1),LEN(CELL("filename",A1))-FIND("]",CELL("filename",A1)))} -> #VALUE! | CP7: 0000 | CR7: FUT Starlight T2 APD DRP | CS7: =-J7 -> 0 | CT7: Change in Unearned Premium Direct | CU7: 100 | CV7: 411100 | CW7: 00 | CX7: 2002 | CY7: 000212 | CZ7: {=RIGHT(CELL("filename",A1),LEN(CELL("filename",A1))-FIND("]",CELL("filename",A1)))} -> #VALUE! | DA7: 0000 | DC7: FUT Starlight T2 APD DRP | DD7: =-K7 -> 0 | DE7: Change in Unearned Premium Direct | DF7: 100 | DG7: 411100 | DH7: 00 | DI7: 2002 | DJ7: 000212 | DK7: {=RIGHT(CELL("filename",A1),LEN(CELL("filename",A1))-FIND("]",CELL("filename",A1)))} -> #VALUE! | DL7: 0000 | DN7: FUT Starlight T2 APD DRP | DO7: =-L7 -> 0 | DP7: Change in Unearned Premium Direct | DQ7: 100 | DR7: 411100 | DS7: 00 | DT7: 2002 | DU7: 000212 | DV7: {=RIGHT(CELL("filename",A1),LEN(CELL("filename",A1))-FIND("]",CELL("filename",A1)))} -> #VALUE! | DW7: 0000 | DY7: FUT Starlight T2 APD DRP | DZ7: =-M7 -> 0 | EA7: Change in Unearned Premium Direct | EB7: 100 | EC7: 411100 | ED7: 00 | EE7: 2002 | EF7: 000212 | EG7: {=RIGHT(CELL("filename",A1),LEN(CELL("filename",A1))-FIND("]",CELL("filename",A1)))} -> #VALUE! | EH7: 0000 | EJ7: FUT Starlight T2 APD DRP | EK7: =-N7 -> 0 | EL7: Change in Unearned Premium Direct | EM7: 100 | EN7: 411100 | EO7: 00 | EP7: 2002 | EQ7: 000212 | ER7: {=RIGHT(CELL("filename",A1),LEN(CELL("filename",A1))-FIND("]",CELL("filename",A1)))} -> #VALUE! | ES7: 0000 | EU7: FUT Starlight T2 APD DRP | EV7: =-O7 -> 0
B8: Premiums Earned | C8: =SUM(C6:C7) -> 0 | D8: =SUM(D6:D7) -> 0 | P8: =SUM(P6:P7) -> 0 | Q8: =SUM(Q6:Q7) -> 0 | R8: =SUM(R6:R7) -> 0 | S8: =SUM(S6:S7) -> 0 | U8: Unearned Premium Direct | V8: 100 | W8: 230100 | X8: 00 | Y8: 2002 | Z8: 000212 | AA8: {=RIGHT(CELL("filename",A1),LEN(CELL("filename",A1))-FIND("]",CELL("filename",A1)))} -> #VALUE! | AB8: 0000 | AD8: FUT Starlight T2 APD DRP | AE8: =D7 -> 0 | AF8: Unearned Premium Direct | AG8: 100 | AH8: 230100 | AI8: 00 | AJ8: 2002 | AK8: 000212 | AL8: {=RIGHT(CELL("filename",A1),LEN(CELL("filename",A1))-FIND("]",CELL("filename",A1)))} -> #VALUE! | AM8: 0000 | AO8: FUT Starlight T2 APD DRP | AP8: =E7 -> 0 | AQ8: Unearned Premium Direct | AR8: 100 | AS8: 230100 | AT8: 00 | AU8: 2002 | AV8: 000212 | AW8: {=RIGHT(CELL("filename",A1),LEN(CELL("filename",A1))-FIND("]",CELL("filename",A1)))} -> #VALUE! | AX8: 0000 | AZ8: FUT Starlight T2 APD DRP | BA8: =+F7 -> 0 | BB8: Unearned Premium Direct | BC8: 100 | BD8: 230100 | BE8: 00 | BF8: 2002 | BG8: 000212 | BH8: {=RIGHT(CELL("filename",A1),LEN(CELL("filename",A1))-FIND("]",CELL("filename",A1)))} -> #VALUE! | BI8: 0000 | BK8: FUT Starlight T2 APD DRP | BL8: =G7 -> 0 | BM8: Unearned Premium Direct | BN8: 100 | BO8: 230100 | BP8: 00 | BQ8: 2002 | BR8: 000212 | BS8: {=RIGHT(CELL("filename",A1),LEN(CELL("filename",A1))-FIND("]",CELL("filename",A1)))} -> #VALUE! | BT8: 0000 | BV8: FUT Starlight T2 APD DRP | BW8: =H7 -> 0 | BX8: Unearned Premium Direct | BY8: 100 | BZ8: 230100 | CA8: 00 | CB8: 2002 | CC8: 000212 | CD8: {=RIGHT(CELL("filename",A1),LEN(CELL("filename",A1))-FIND("]",CELL("filename",A1)))} -> #VALUE! | CE8: 0000 | CG8: FUT Starlight T2 APD DRP | CH8: =I7 -> 0 | CI8: Unearned Premium Direct | CJ8: 100 | CK8: 230100 | CL8: 00 | CM8: 2002 | CN8: 000212 | CO8: {=RIGHT(CELL("filename",A1),LEN(CELL("filename",A1))-FIND("]",CELL("filename",A1)))} -> #VALUE! | CP8: 0000 | CR8: FUT Starlight T2 APD DRP | CS8: =J7 -> 0 | CT8: Unearned Premium Direct | CU8: 100 | CV8: 230100 | CW8: 00 | CX8: 2002 | CY8: 000212 | CZ8: {=RIGHT(CELL("filename",A1),LEN(CELL("filename",A1))-FIND("]",CELL("filename",A1)))} -> #VALUE! | DA8: 0000 | DC8: FUT Starlight T2 APD DRP | DD8: =K7 -> 0 | DE8: Unearned Premium Direct | DF8: 100 | DG8: 230100 | DH8: 00 | DI8: 2002 | DJ8: 000212 | DK8: {=RIGHT(CELL("filename",A1),LEN(CELL("filename",A1))-FIND("]",CELL("filename",A1)))} -> #VALUE! | DL8: 0000 | DN8: FUT Starlight T2 APD DRP | DO8: =L7 -> 0 | DP8: Unearned Premium Direct | DQ8: 100 | DR8: 230100 | DS8: 00 | DT8: 2002 | DU8: 000212 | DV8: {=RIGHT(CELL("filename",A1),LEN(CELL("filename",A1))-FIND("]",CELL("filename",A1)))} -> #VALUE! | DW8: 0000 | DY8: FUT Starlight T2 APD DRP | DZ8: =M7 -> 0 | EA8: Unearned Premium Direct | EB8: 100 | EC8: 230100 | ED8: 00 | EE8: 2002 | EF8: 000212 | EG8: {=RIGHT(CELL("filename",A1),LEN(CELL("filename",A1))-FIND("]",CELL("filename",A1)))} -> #VALUE! | EH8: 0000 | EJ8: FUT Starlight T2 APD DRP | EK8: =N7 -> 0 | EL8: Unearned Premium Direct | EM8: 100 | EN8: 230100 | EO8: 00 | EP8: 2002 | EQ8: 000212 | ER8: {=RIGHT(CELL("filename",A1),LEN(CELL("filename",A1))-FIND("]",CELL("filename",A1)))} -> #VALUE! | ES8: 0000 | EU8: FUT Starlight T2 APD DRP | EV8: =O7 -> 0
U9: Ceded Premium Written | V9: 100 | W9: 400300 | X9: 00 | Y9: 2002 | Z9: 000212 | AA9: 00 | AB9: 0000 | AD9: FUT Starlight T2 APD DRP | AE9: =+D6 -> 0 | AF9: Ceded Premium Written | AG9: 100 | AH9: 400300 | AI9: 00 | AJ9: 2002 | AK9: 000212 | AL9: 00 | AM9: 0000 | AO9: FUT Starlight T2 APD DRP | AP9: =+E6 -> 0 | AQ9: Ceded Premium Written | AR9: 100 | AS9: 400300 | AT9: 00 | AU9: 2002 | AV9: 000212 | AW9: 00 | AX9: 0000 | AZ9: FUT Starlight T2 APD DRP | BA9: =+F6 -> 0 | BB9: Ceded Premium Written | BC9: 100 | BD9: 400300 | BE9: 00 | BF9: 2002 | BG9: 000212 | BH9: 00 | BI9: 0000 | BK9: FUT Starlight T2 APD DRP | BL9: =+G6 -> 0 | BM9: Ceded Premium Written | BN9: 100 | BO9: 400300 | BP9: 00 | BQ9: 2002 | BR9: 000212 | BS9: 00 | BT9: 0000 | BV9: FUT Starlight T2 APD DRP | BW9: =+H6 -> 0 | BX9: Ceded Premium Written | BY9: 100 | BZ9: 400300 | CA9: 00 | CB9: 2002 | CC9: 000212 | CD9: 00 | CE9: 0000 | CG9: FUT Starlight T2 APD DRP | CH9: =+I6 -> 0 | CI9: Ceded Premium Written | CJ9: 100 | CK9: 400300 | CL9: 00 | CM9: 2002 | CN9: 000212 | CO9: 00 | CP9: 0000 | CR9: FUT Starlight T2 APD DRP | CS9: =+J6 -> 0 | CT9: Ceded Premium Written | CU9: 100 | CV9: 400300 | CW9: 00 | CX9: 2002 | CY9: 000212 | CZ9: 00 | DA9: 0000 | DC9: FUT Starlight T2 APD DRP | DD9: =+K6 -> 0 | DE9: Ceded Premium Written | DF9: 100 | DG9: 400300 | DH9: 00 | DI9: 2002 | DJ9: 000212 | DK9: 00 | DL9: 0000 | DN9: FUT Starlight T2 APD DRP | DO9: =+L6 -> 0 | DP9: Ceded Premium Written | DQ9: 100 | DR9: 400300 | DS9: 00 | DT9: 2002 | DU9: 000212 | DV9: 00 | DW9: 0000 | DY9: FUT Starlight T2 APD DRP | DZ9: =+M6 -> 0 | EA9: Ceded Premium Written | EB9: 100 | EC9: 400300 | ED9: 00 | EE9: 2002 | EF9: 000212 | EG9: 00 | EH9: 0000 | EJ9: FUT Starlight T2 APD DRP | EK9: =+N6 -> 0 | EL9: Ceded Premium Written | EM9: 100 | EN9: 400300 | EO9: 00 | EP9: 2002 | EQ9: 000212 | ER9: 00 | ES9: 0000 | EU9: FUT Starlight T2 APD DRP | EV9: =+O6 -> 0
B10: Less: | U10: Ceded Reinsurance Premiums Payable | V10: 100 | W10: 243100 | X10: 00 | Y10: 2002 | Z10: 000212 | AA10: 00 | AB10: 0000 | AD10: FUT Starlight T2 APD DRP | AE10: =-D6 -> 0 | AF10: Ceded Reinsurance Premiums Payable | AG10: 100 | AH10: 243100 | AI10: 00 | AJ10: 2002 | AK10: 000212 | AL10: 00 | AM10: 0000 | AO10: FUT Starlight T2 APD DRP | AP10: =-E6 -> 0 | AQ10: Ceded Reinsurance Premiums Payable | AR10: 100 | AS10: 243100 | AT10: 00 | AU10: 2002 | AV10: 000212 | AW10: 00 | AX10: 0000 | AZ10: FUT Starlight T2 APD DRP | BA10: =-F6 -> 0 | BB10: Ceded Reinsurance Premiums Payable | BC10: 100 | BD10: 243100 | BE10: 00 | BF10: 2002 | BG10: 000212 | BH10: 00 | BI10: 0000 | BK10: FUT Starlight T2 APD DRP | BL10: =-G6 -> 0 | BM10: Ceded Reinsurance Premiums Payable | BN10: 100 | BO10: 243100 | BP10: 00 | BQ10: 2002 | BR10: 000212 | BS10: 00 | BT10: 0000 | BV10: FUT Starlight T2 APD DRP | BW10: =-H6 -> 0 | BX10: Ceded Reinsurance Premiums Payable | BY10: 100 | BZ10: 243100 | CA10: 00 | CB10: 2002 | CC10: 000212 | CD10: 00 | CE10: 0000 | CG10: FUT Starlight T2 APD DRP | CH10: =-I6 -> 0 | CI10: Ceded Reinsurance Premiums Payable | CJ10: 100 | CK10: 243100 | CL10: 00 | CM10: 2002 | CN10: 000212 | CO10: 00 | CP10: 0000 | CR10: FUT Starlight T2 APD DRP | CS10: =-J6 -> 0 | CT10: Ceded Reinsurance Premiums Payable | CU10: 100 | CV10: 243100 | CW10: 00 | CX10: 2002 | CY10: 000212 | CZ10: 00 | DA10: 0000 | DC10: FUT Starlight T2 APD DRP | DD10: =-K6 -> 0 | DE10: Ceded Reinsurance Premiums Payable | DF10: 100 | DG10: 243100 | DH10: 00 | DI10: 2002 | DJ10: 000212 | DK10: 00 | DL10: 0000 | DN10: FUT Starlight T2 APD DRP | DO10: =-L6 -> 0 | DP10: Ceded Reinsurance Premiums Payable | DQ10: 100 | DR10: 243100 | DS10: 00 | DT10: 2002 | DU10: 000212 | DV10: 00 | DW10: 0000 | DY10: FUT Starlight T2 APD DRP | DZ10: =-M6 -> 0 | EA10: Ceded Reinsurance Premiums Payable | EB10: 100 | EC10: 243100 | ED10: 00 | EE10: 2002 | EF10: 000212 | EG10: 00 | EH10: 0000 | EJ10: FUT Starlight T2 APD DRP | EK10: =-N6 -> 0 | EL10: Ceded Reinsurance Premiums Payable | EM10: 100 | EN10: 243100 | EO10: 00 | EP10: 2002 | EQ10: 000212 | ER10: 00 | ES10: 0000 | EU10: FUT Starlight T2 APD DRP | EV10: =-O6 -> 0
A11: b. | B11: Ceding Commissions at 29% | C11: 0 | D11: =+D6*0.29 -> 0 | P11: =SUM(D11:O11) -> 0 | Q11: =+C11+P11 -> 0 | U11: Unearned Premium Ceded | V11: 100 | W11: 230300 | X11: 00 | Y11: 2002 | Z11: 000212 | AA11: 00 | AB11: 0000 | AD11: FUT Starlight T2 APD DRP | AE11: =-D7 -> 0 | AF11: Unearned Premium Ceded | AG11: 100 | AH11: 230300 | AI11: 00 | AJ11: 2002 | AK11: 000212 | AL11: 00 | AM11: 0000 | AO11: FUT Starlight T2 APD DRP | AP11: =-E7 -> 0 | AQ11: Unearned Premium Ceded | AR11: 100 | AS11: 230300 | AT11: 00 | AU11: 2002 | AV11: 000212 | AW11: 00 | AX11: 0000 | AZ11: FUT Starlight T2 APD DRP | BA11: =-F7 -> 0 | BB11: Unearned Premium Ceded | BC11: 100 | BD11: 230300 | BE11: 00 | BF11: 2002 | BG11: 000212 | BH11: 00 | BI11: 0000 | BK11: FUT Starlight T2 APD DRP | BL11: =-G7 -> 0 | BM11: Unearned Premium Ceded | BN11: 100 | BO11: 230300 | BP11: 00 | BQ11: 2002 | BR11: 000212 | BS11: 00 | BT11: 0000 | BV11: FUT Starlight T2 APD DRP | BW11: =-H7 -> 0 | BX11: Unearned Premium Ceded | BY11: 100 | BZ11: 230300 | CA11: 00 | CB11: 2002 | CC11: 000212 | CD11: 00 | CE11: 0000 | CG11: FUT Starlight T2 APD DRP | CH11: =-I7 -> 0 | CI11: Unearned Premium Ceded | CJ11: 100 | CK11: 230300 | CL11: 00 | CM11: 2002 | CN11: 000212 | CO11: 00 | CP11: 0000 | CR11: FUT Starlight T2 APD DRP | CS11: =-J7 -> 0 | CT11: Unearned Premium Ceded | CU11: 100 | CV11: 230300 | CW11: 00 | CX11: 2002 | CY11: 000212 | CZ11: 00 | DA11: 0000 | DC11: FUT Starlight T2 APD DRP | DD11: =-K7 -> 0 | DE11: Unearned Premium Ceded | DF11: 100 | DG11: 230300 | DH11: 00 | DI11: 2002 | DJ11: 000212 | DK11: 00 | DL11: 0000 | DN11: FUT Starlight T2 APD DRP | DO11: =-L7 -> 0 | DP11: Unearned Premium Ceded | DQ11: 100 | DR11: 230300 | DS11: 00 | DT11: 2002 | DU11: 000212 | DV11: 00 | DW11: 0000 | DY11: FUT Starlight T2 APD DRP | DZ11: =-M7 -> 0 | EA11: Unearned Premium Ceded | EB11: 100 | EC11: 230300 | ED11: 00 | EE11: 2002 | EF11: 000212 | EG11: 00 | EH11: 0000 | EJ11: FUT Starlight T2 APD DRP | EK11: =-N7 -> 0 | EL11: Unearned Premium Ceded | EM11: 100 | EN11: 230300 | EO11: 00 | EP11: 2002 | EQ11: 000212 | ER11: 00 | ES11: 0000 | EU11: FUT Starlight T2 APD DRP | EV11: =-O7 -> 0
B12: Ceding Commissions on UEP | C12: 0 | D12: 0 | P12: =SUM(D12:O12) -> 0 | Q12: =+C12+P12 -> 0 | U12: Change in Unearned Premium Ceded | V12: 100 | W12: 411300 | X12: 00 | Y12: 2002 | Z12: 000212 | AA12: 00 | AB12: 0000 | AD12: FUT Starlight T2 APD DRP | AE12: =D7 -> 0 | AF12: Change in Unearned Premium Ceded | AG12: 100 | AH12: 411300 | AI12: 00 | AJ12: 2002 | AK12: 000212 | AL12: 00 | AM12: 0000 | AO12: FUT Starlight T2 APD DRP | AP12: =E7 -> 0 | AQ12: Change in Unearned Premium Ceded | AR12: 100 | AS12: 411300 | AT12: 00 | AU12: 2002 | AV12: 000212 | AW12: 00 | AX12: 0000 | AZ12: FUT Starlight T2 APD DRP | BA12: =+F7 -> 0 | BB12: Change in Unearned Premium Ceded | BC12: 100 | BD12: 411300 | BE12: 00 | BF12: 2002 | BG12: 000212 | BH12: 00 | BI12: 0000 | BK12: FUT Starlight T2 APD DRP | BL12: =G7 -> 0 | BM12: Change in Unearned Premium Ceded | BN12: 100 | BO12: 411300 | BP12: 00 | BQ12: 2002 | BR12: 000212 | BS12: 00 | BT12: 0000 | BV12: FUT Starlight T2 APD DRP | BW12: =H7 -> 0 | BX12: Change in Unearned Premium Ceded | BY12: 100 | BZ12: 411300 | CA12: 00 | CB12: 2002 | CC12: 000212 | CD12: 00 | CE12: 0000 | CG12: FUT Starlight T2 APD DRP | CH12: =I7 -> 0 | CI12: Change in Unearned Premium Ceded | CJ12: 100 | CK12: 411300 | CL12: 00 | CM12: 2002 | CN12: 000212 | CO12: 00 | CP12: 0000 | CR12: FUT Starlight T2 APD DRP | CS12: =J7 -> 0 | CT12: Change in Unearned Premium Ceded | CU12: 100 | CV12: 411300 | CW12: 00 | CX12: 2002 | CY12: 000212 | CZ12: 00 | DA12: 0000 | DC12: FUT Starlight T2 APD DRP | DD12: =K7 -> 0 | DE12: Change in Unearned Premium Ceded | DF12: 100 | DG12: 411300 | DH12: 00 | DI12: 2002 | DJ12: 000212 | DK12: 00 | DL12: 0000 | DN12: FUT Starlight T2 APD DRP | DO12: =L7 -> 0 | DP12: Change in Unearned Premium Ceded | DQ12: 100 | DR12: 411300 | DS12: 00 | DT12: 2002 | DU12: 000212 | DV12: 00 | DW12: 0000 | DY12: FUT Starlight T2 APD DRP | DZ12: =M7 -> 0 | EA12: Change in Unearned Premium Ceded | EB12: 100 | EC12: 411300 | ED12: 00 | EE12: 2002 | EF12: 000212 | EG12: 00 | EH12: 0000 | EJ12: FUT Starlight T2 APD DRP | EK12: =N7 -> 0 | EL12: Change in Unearned Premium Ceded | EM12: 100 | EN12: 411300 | EO12: 00 | EP12: 2002 | EQ12: 000212 | ER12: 00 | ES12: 0000 | EU12: FUT Starlight T2 APD DRP | EV12: =O7 -> 0
B13: Ceding Commissions Earned | C13: =SUM(C11:C12) -> 0 | D13: =SUM(D11:D12) -> 0 | P13: =SUM(P11:P12) -> 0 | Q13: =SUM(Q11:Q12) -> 0 | U13: Commissions Direct | V13: 100 | W13: 500100 | X13: 00 | Y13: 2002 | Z13: 000212 | AA13: {=RIGHT(CELL("filename",A1),LEN(CELL("filename",A1))-FIND("]",CELL("filename",A1)))} -> #VALUE! | AB13: 0000 | AD13: FUT Starlight T2 APD DRP | AE13: =+D11 -> 0 | AF13: Commissions Direct | AG13: 100 | AH13: 500100 | AI13: 00 | AJ13: 2002 | AK13: 000212 | AL13: {=RIGHT(CELL("filename",A1),LEN(CELL("filename",A1))-FIND("]",CELL("filename",A1)))} -> #VALUE! | AM13: 0000 | AO13: FUT Starlight T2 APD DRP | AP13: =+E11 -> 0 | AQ13: Commissions Direct | AR13: 100 | AS13: 500100 | AT13: 00 | AU13: 2002 | AV13: 000212 | AW13: {=RIGHT(CELL("filename",A1),LEN(CELL("filename",A1))-FIND("]",CELL("filename",A1)))} -> #VALUE! | AX13: 0000 | AZ13: FUT Starlight T2 APD DRP | BA13: =+F11 -> 0 | BB13: Commissions Direct | BC13: 100 | BD13: 500100 | BE13: 00 | BF13: 2002 | BG13: 000212 | BH13: {=RIGHT(CELL("filename",A1),LEN(CELL("filename",A1))-FIND("]",CELL("filename",A1)))} -> #VALUE! | BI13: 0000 | BK13: FUT Starlight T2 APD DRP | BL13: =+G11 -> 0 | BM13: Commissions Direct | BN13: 100 | BO13: 500100 | BP13: 00 | BQ13: 2002 | BR13: 000212 | BS13: {=RIGHT(CELL("filename",A1),LEN(CELL("filename",A1))-FIND("]",CELL("filename",A1)))} -> #VALUE! | BT13: 0000 | BV13: FUT Starlight T2 APD DRP | BW13: =+H11 -> 0 | BX13: Commissions Direct | BY13: 100 | BZ13: 500100 | CA13: 00 | CB13: 2002 | CC13: 000212 | CD13: {=RIGHT(CELL("filename",A1),LEN(CELL("filename",A1))-FIND("]",CELL("filename",A1)))} -> #VALUE! | CE13: 0000 | CG13: FUT Starlight T2 APD DRP | CH13: =+I11 -> 0 | CI13: Commissions Direct | CJ13: 100 | CK13: 500100 | CL13: 00 | CM13: 2002 | CN13: 000212 | CO13: {=RIGHT(CELL("filename",A1),LEN(CELL("filename",A1))-FIND("]",CELL("filename",A1)))} -> #VALUE! | CP13: 0000 | CR13: FUT Starlight T2 APD DRP | CS13: =+J11 -> 0 | CT13: Commissions Direct | CU13: 100 | CV13: 500100 | CW13: 00 | CX13: 2002 | CY13: 000212 | CZ13: {=RIGHT(CELL("filename",A1),LEN(CELL("filename",A1))-FIND("]",CELL("filename",A1)))} -> #VALUE! | DA13: 0000 | DC13: FUT Starlight T2 APD DRP | DD13: =+K11 -> 0 | DE13: Commissions Direct | DF13: 100 | DG13: 500100 | DH13: 00 | DI13: 2002 | DJ13: 000212 | DK13: {=RIGHT(CELL("filename",A1),LEN(CELL("filename",A1))-FIND("]",CELL("filename",A1)))} -> #VALUE! | DL13: 0000 | DN13: FUT Starlight T2 APD DRP | DO13: =+L11 -> 0 | DP13: Commissions Direct | DQ13: 100 | DR13: 500100 | DS13: 00 | DT13: 2002 | DU13: 000212 | DV13: {=RIGHT(CELL("filename",A1),LEN(CELL("filename",A1))-FIND("]",CELL("filename",A1)))} -> #VALUE! | DW13: 0000 | DY13: FUT Starlight T2 APD DRP | DZ13: =+M11 -> 0 | EA13: Commissions Direct | EB13: 100 | EC13: 500100 | ED13: 00 | EE13: 2002 | EF13: 000212 | EG13: {=RIGHT(CELL("filename",A1),LEN(CELL("filename",A1))-FIND("]",CELL("filename",A1)))} -> #VALUE! | EH13: 0000 | EJ13: FUT Starlight T2 APD DRP | EK13: =+N11 -> 0 | EL13: Commissions Direct | EM13: 100 | EN13: 500100 | EO13: 00 | EP13: 2002 | EQ13: 000212 | ER13: {=RIGHT(CELL("filename",A1),LEN(CELL("filename",A1))-FIND("]",CELL("filename",A1)))} -> #VALUE! | ES13: 0000 | EU13: FUT Starlight T2 APD DRP | EV13: =+O11 -> 0
U14: Uncollected Premium Direct | V14: 100 | W14: 120100 | X14: 00 | Y14: 2002 | Z14: 000212 | AA14: 00 | AB14: 0000 | AD14: FUT Starlight T2 APD DRP | AE14: =-D11 -> 0 | AF14: Uncollected Premium Direct | AG14: 100 | AH14: 120100 | AI14: 00 | AJ14: 2002 | AK14: 000212 | AL14: 00 | AM14: 0000 | AO14: FUT Starlight T2 APD DRP | AP14: =-E11 -> 0 | AQ14: Uncollected Premium Direct | AR14: 100 | AS14: 120100 | AT14: 00 | AU14: 2002 | AV14: 000212 | AW14: 00 | AX14: 0000 | AZ14: FUT Starlight T2 APD DRP | BA14: =-F11 -> 0 | BB14: Uncollected Premium Direct | BC14: 100 | BD14: 120100 | BE14: 00 | BF14: 2002 | BG14: 000212 | BH14: 00 | BI14: 0000 | BK14: FUT Starlight T2 APD DRP | BL14: =-G11 -> 0 | BM14: Uncollected Premium Direct | BN14: 100 | BO14: 120100 | BP14: 00 | BQ14: 2002 | BR14: 000212 | BS14: 00 | BT14: 0000 | BV14: FUT Starlight T2 APD DRP | BW14: =-H11 -> 0 | BX14: Uncollected Premium Direct | BY14: 100 | BZ14: 120100 | CA14: 00 | CB14: 2002 | CC14: 000212 | CD14: 00 | CE14: 0000 | CG14: FUT Starlight T2 APD DRP | CH14: =-I11 -> 0 | CI14: Uncollected Premium Direct | CJ14: 100 | CK14: 120100 | CL14: 00 | CM14: 2002 | CN14: 000212 | CO14: 00 | CP14: 0000 | CR14: FUT Starlight T2 APD DRP | CS14: =-J11 -> 0 | CT14: Uncollected Premium Direct | CU14: 100 | CV14: 120100 | CW14: 00 | CX14: 2002 | CY14: 000212 | CZ14: 00 | DA14: 0000 | DC14: FUT Starlight T2 APD DRP | DD14: =-K11 -> 0 | DE14: Uncollected Premium Direct | DF14: 100 | DG14: 120100 | DH14: 00 | DI14: 2002 | DJ14: 000212 | DK14: 00 | DL14: 0000 | DN14: FUT Starlight T2 APD DRP | DO14: =-L11 -> 0 | DP14: Uncollected Premium Direct | DQ14: 100 | DR14: 120100 | DS14: 00 | DT14: 2002 | DU14: 000212 | DV14: 00 | DW14: 0000 | DY14: FUT Starlight T2 APD DRP | DZ14: =-M11 -> 0 | EA14: Uncollected Premium Direct | EB14: 100 | EC14: 120100 | ED14: 00 | EE14: 2002 | EF14: 000212 | EG14: 00 | EH14: 0000 | EJ14: FUT Starlight T2 APD DRP | EK14: =-N11 -> 0 | EL14: Uncollected Premium Direct | EM14: 100 | EN14: 120100 | EO14: 00 | EP14: 2002 | EQ14: 000212 | ER14: 00 | ES14: 0000 | EU14: FUT Starlight T2 APD DRP | EV14: =-O11 -> 0
